Workbook

Sheet How to use
A1: GOOOAL — Test League Scorer / حاسبة نقاط الدوري التجريبي
A3: Yellow cells = you type here. White/grey cells = formulas (don't edit). Green rows = EXAMPLE data: delete them before week 1.
A4: الخلايا الصفراء = للإدخال. الخلايا الأخرى معادلات (لا تعدّلها). الصفوف الخضراء = أمثلة، احذفها قبل الأسبوع الأول.
A6: Weekly steps:
A7: 1. Clubs: check the club list (edit freely).
A8: 2. Players: add each new player once (name exactly as they type it in the form + primary club).
A9: 3. Matches: add this week's matches (Week, Match # 1–10, teams, kick-off). After each match, type the 90-minute score. If a match is postponed/cancelled, set Status = Void.
A10: 4. Predictions: paste the Google Form responses: Week, Player name, Timestamp, then home/away goals for matches 1–10 in order.
A11: 5. Leaderboard: choose the week in cell B2 (yellow). Screenshot the Week and Season tables and post them in the group.
A12: 6. Club vs Club: same week selection. Post the table: this is the key feature we're testing.
A13: 7. Tracking: type invites/feedback notes each week. Participation and retention calculate automatically.
A15: Scoring rules (approved D-019):
... A22: Limits: 200 players, 200 matches, 2,000 prediction rows (one row = one player's picks for one week).

Sheet Clubs
A1: Club / النادي | B1: League / الدوري | D1: Edit or add clubs in rows 2–61. This list feeds the Players drop-down.
A2: Al Hilal | B2: Saudi Pro League
A3: Al Nassr | B3: Saudi Pro League
A4: Al Ittihad | B4: Saudi Pro League
A5: Al Ahli | B5: Saudi Pro League
A6: Al Shabab | B6: Saudi Pro League
A7: Al Ettifaq | B7: Saudi Pro League
A8: Al Taawoun | B8: Saudi Pro League
A9: Al Fateh | B9: Saudi Pro League
A10: Al Qadsiah | B10: Saudi Pro League
A11: Al Ain | B11: UAE Pro League
A12: Al Wahda | B12: UAE Pro League
A13: Al Jazira | B13: UAE Pro League
... A28: Paris Saint-Germain | B28: Ligue 1

Sheet Players
A1: Player name (exactly as in form) / اسم اللاعب | B1: Primary club / النادي المفضل | C1: Country | D1: Joined in week | E1: Invited by (player name)
A2: Example – Faisal | B2: Al Hilal | C2: KSA | D2: 1
A3: Example – Khalid | B3: Al Nassr | C3: KSA | D3: 1 | E3: Example – Faisal
A4: Example – Omar | B4: Al Ain | C4: UAE | D4: 1

Sheet Matches
A1: Week | B1: Match # (1–10) | C1: Home team | D1: Away team | E1: Competition | F1: Kick-off (date & time) | G1: Home goals (90') | H1: Away goals (90') | I1: Status (blank = normal, Void) | J1: Key (auto)
A2: 1 | B2: 1 | C2: Al Hilal | D2: Al Nassr | E2: Saudi Pro League | F2: 46297.875 | G2: 2 | H2: 1 | J2: =IF(OR(A2="",B2=""),"",A2&"-"&B2) -> 1-1
A3: 1 | B3: 2 | C3: Real Madrid | D3: Barcelona | E3: La Liga | F3: 46298.917 | G3: 1 | H3: 1 | J3: =IF(OR(A3="",B3=""),"",A3&"-"&B3) -> 1-2
A4: 1 | B4: 3 | C4: Al Ain | D4: Al Wahda | E4: UAE Pro League | F4: 46299.792 | G4: 0 | H4: 2 | J4: =IF(OR(A4="",B4=""),"",A4&"-"&B4) -> 1-3
J5: =IF(OR(A5="",B5=""),"",A5&"-"&B5)
J6: =IF(OR(A6="",B6=""),"",A6&"-"&B6)
J7: =IF(OR(A7="",B7=""),"",A7&"-"&B7)
J8: =IF(OR(A8="",B8=""),"",A8&"-"&B8)
J9: =IF(OR(A9="",B9=""),"",A9&"-"&B9)
J10: =IF(OR(A10="",B10=""),"",A10&"-"&B10)
J11: =IF(OR(A11="",B11=""),"",A11&"-"&B11)
J12: =IF(OR(A12="",B12=""),"",A12&"-"&B12)
J13: =IF(OR(A13="",B13=""),"",A13&"-"&B13)
J14: =IF(OR(A14="",B14=""),"",A14&"-"&B14)
J15: =IF(OR(A15="",B15=""),"",A15&"-"&B15)
J16: =IF(OR(A16="",B16=""),"",A16&"-"&B16)
... J201: =IF(OR(A201="",B201=""),"",A201&"-"&B201)

Sheet Predictions
A1: Week | B1: Player name | C1: Form timestamp | D1: M1 home | E1: M1 away | F1: M2 home | G1: M2 away | H1: M3 home | I1: M3 away | J1: M4 home | K1: M4 away | L1: M5 home | M1: M5 away | N1: M6 home | O1: M6 away | P1: M7 home | Q1: M7 away | R1: M8 home | S1: M8 away | T1: M9 home | U1: M9 away | V1: M10 home | W1: M10 away | X1: Pts M1 | Y1: Pts M2 | Z1: Pts M3 | AA1: Pts M4 | AB1: Pts M5 | AC1: Pts M6 | AD1: Pts M7 | AE1: Pts M8 | AF1: Pts M9 | AG1: Pts M10 | AH1: Week points | AI1: Exact scores | AJ1: Correct results | AK1: Settled picks
A2: 1 | B2: Example – Faisal | C2: 46296.753 | D2: 2 | E2: 1 | F2: 2 | G2: 1 | H2: 1 | I2: 1 | X2: =IF(OR($B2="",D2="",E2=""),"",IFERROR(IF(OR(INDEX(Matches!$I$2:$I$201,MATCH($A2&"-1",Matches!$J$2:$J$201,0))="Void",INDEX(Matches!$G$2:$G$201,MATCH($A2&"-1",Matches!$J$2:$J$201,0))="",INDEX(Matches!$H$2:$H$201,MATCH($A2&"-1",Matches!$J$2:$J$201,0))=""),"",IF(AND($C2<>"",INDEX(Matches!$F$2:$F$201,MATCH($A2&"-1",Matches!$J$2:$J$201,0))<>"",$C2>=INDEX(Matches!$F$2:$F$201,MATCH($A2&"-1",Matches!$J$2:$J$201,0))),"",IF(AND(D2=INDEX(Matches!$G$2:$G$201,MATCH($A2&"-1",Matches!$J$2:$J$201,0)),E2=INDEX(Matches!$H$2:$H$201,MATCH($A2&"-1",Matches!$J$2:$J$201,0))),5,IF(SIGN(D2-E2)<>SIGN(INDEX(Matches!$G$2:$G$201,MATCH($A2&"-1",Matches!$J$2:$J$201,0))-INDEX(Matches!$H$2:$H$201,MATCH($A2&"-1",Matches!$J$2:$J$201,0))),0,IF(D2-E2=INDEX(Matches!$G$2:$G$201,MATCH($A2&"-1",Matches!$J$2:$J$201,0))-INDEX(Matches!$H$2:$H$201,MATCH($A2&"-1",Matches!$J$2:$J$201,0)),3,2))))),"")) -> 5 | Y2: =IF(OR($B2="",F2="",G2=""),"",IFERROR(IF(OR(INDEX(Matches!$I$2:$I$201,MATCH($A2&"-2",Matches!$J$2:$J$201,0))="Void",INDEX(Matches!$G$2:$G$201,MATCH($A2&"-2",Matches!$J$2:$J$201,0))="",INDEX(Matches!$H$2:$H$201,MATCH($A2&"-2",Matches!$J$2:$J$201,0))=""),"",IF(AND($C2<>"",INDEX(Matches!$F$2:$F$201,MATCH($A2&"-2",Matches!$J$2:$J$201,0))<>"",$C2>=INDEX(Matches!$F$2:$F$201,MATCH($A2&"-2",Matches!$J$2:$J$201,0))),"",IF(AND(F2=INDEX(Matches!$G$2:$G$201,MATCH($A2&"-2",Matches!$J$2:$J$201,0)),G2=INDEX(Matches!$H$2:$H$201,MATCH($A2&"-2",Matches!$J$2:$J$201,0))),5,IF(SIGN(F2-G2)<>SIGN(INDEX(Matches!$G$2:$G$201,MATCH($A2&"-2",Matches!$J$2:$J$201,0))-INDEX(Matches!$H$2:$H$201,MATCH($A2&"-2",Matches!$J$2:$J$201,0))),0,IF(F2-G2=INDEX(Matches!$G$2:$G$201,MATCH($A2&"-2",Matches!$J$2:$J$201,0))-INDEX(Matches!$H$2:$H$201,MATCH($A2&"-2",Matches!$J$2:$J$201,0)),3,2))))),"")) -> 0 | Z2: =IF(OR($B2="",H2="",I2=""),"",IFERROR(IF(OR(INDEX(Matches!$I$2:$I$201,MATCH($A2&"-3",Matches!$J$2:$J$201,0))="Void",INDEX(Matches!$G$2:$G$201,MATCH($A2&"-3",Matches!$J$2:$J$201,0))="",INDEX(Matches!$H$2:$H$201,MATCH($A2&"-3",Matches!$J$2:$J$201,0))=""),"",IF(AND($C2<>"",INDEX(Matches!$F$2:$F$201,MATCH($A2&"-3",Matches!$J$2:$J$201,0))<>"",$C2>=INDEX(Matches!$F$2:$F$201,MATCH($A2&"-3",Matches!$J$2:$J$201,0))),"",IF(AND(H2=INDEX(Matches!$G$2:$G$201,MATCH($A2&"-3",Matches!$J$2:$J$201,0)),I2=INDEX(Matches!$H$2:$H$201,MATCH($A2&"-3",Matches!$J$2:$J$201,0))),5,IF(SIGN(H2-I2)<>SIGN(INDEX(Matches!$G$2:$G$201,MATCH($A2&"-3",Matches!$J$2:$J$201,0))-INDEX(Matches!$H$2:$H$201,MATCH($A2&"-3",Matches!$J$2:$J$201,0))),0,IF(H2-I2=INDEX(Matches!$G$2:$G$201,MATCH($A2&"-3",Matches!$J$2:$J$201,0))-INDEX(Matches!$H$2:$H$201,MATCH($A2&"-3",Matches!$J$2:$J$201,0)),3,2))))),"")) -> 0 | AA2: =IF(OR($B2="",J2="",K2=""),"",IFERROR(IF(OR(INDEX(Matches!$I$2:$I$201,MATCH($A2&"-4",Matches!$J$2:$J$201,0))="Void",INDEX(Matches!$G$2:$G$201,MATCH($A2&"-4",Matches!$J$2:$J$201,0))="",INDEX(Matches!$H$2:$H$201,MATCH($A2&"-4",Matches!$J$2:$J$201,0))=""),"",IF(AND($C2<>"",INDEX(Matches!$F$2:$F$201,MATCH($A2&"-4",Matches!$J$2:$J$201,0))<>"",$C2>=INDEX(Matches!$F$2:$F$201,MATCH($A2&"-4",Matches!$J$2:$J$201,0))),"",IF(AND(J2=INDEX(Matches!$G$2:$G$201,MATCH($A2&"-4",Matches!$J$2:$J$201,0)),K2=INDEX(Matches!$H$2:$H$201,MATCH($A2&"-4",Matches!$J$2:$J$201,0))),5,IF(SIGN(J2-K2)<>SIGN(INDEX(Matches!$G$2:$G$201,MATCH($A2&"-4",Matches!$J$2:$J$201,0))-INDEX(Matches!$H$2:$H$201,MATCH($A2&"-4",Matches!$J$2:$J$201,0))),0,IF(J2-K2=INDEX(Matches!$G$2:$G$201,MATCH($A2&"-4",Matches!$J$2:$J$201,0))-INDEX(Matches!$H$2:$H$201,MATCH($A2&"-4",Matches!$J$2:$J$201,0)),3,2))))),"")) | AB2: =IF(OR($B2="",L2="",M2=""),"",IFERROR(IF(OR(INDEX(Matches!$I$2:$I$201,MATCH($A2&"-5",Matches!$J$2:$J$201,0))="Void",INDEX(Matches!$G$2:$G$201,MATCH($A2&"-5",Matches!$J$2:$J$201,0))="",INDEX(Matches!$H$2:$H$201,MATCH($A2&"-5",Matches!$J$2:$J$201,0))=""),"",IF(AND($C2<>"",INDEX(Matches!$F$2:$F$201,MATCH($A2&"-5",Matches!$J$2:$J$201,0))<>"",$C2>=INDEX(Matches!$F$2:$F$201,MATCH($A2&"-5",Matches!$J$2:$J$201,0))),"",IF(AND(L2=INDEX(Matches!$G$2:$G$201,MATCH($A2&"-5",Matches!$J$2:$J$201,0)),M2=INDEX(Matches!$H$2:$H$201,MATCH($A2&"-5",Matches!$J$2:$J$201,0))),5,IF(SIGN(L2-M2)<>SIGN(INDEX(Matches!$G$2:$G$201,MATCH($A2&"-5",Matches!$J$2:$J$201,0))-INDEX(Matches!$H$2:$H$201,MATCH($A2&"-5",Matches!$J$2:$J$201,0))),0,IF(L2-M2=INDEX(Matches!$G$2:$G$201,MATCH($A2&"-5",Matches!$J$2:$J$201,0))-INDEX(Matches!$H$2:$H$201,MATCH($A2&"-5",Matches!$J$2:$J$201,0)),3,2))))),"")) | AC2: =IF(OR($B2="",N2="",O2=""),"",IFERROR(IF(OR(INDEX(Matches!$I$2:$I$201,MATCH($A2&"-6",Matches!$J$2:$J$201,0))="Void",INDEX(Matches!$G$2:$G$201,MATCH($A2&"-6",Matches!$J$2:$J$201,0))="",INDEX(Matches!$H$2:$H$201,MATCH($A2&"-6",Matches!$J$2:$J$201,0))=""),"",IF(AND($C2<>"",INDEX(Matches!$F$2:$F$201,MATCH($A2&"-6",Matches!$J$2:$J$201,0))<>"",$C2>=INDEX(Matches!$F$2:$F$201,MATCH($A2&"-6",Matches!$J$2:$J$201,0))),"",IF(AND(N2=INDEX(Matches!$G$2:$G$201,MATCH($A2&"-6",Matches!$J$2:$J$201,0)),O2=INDEX(Matches!$H$2:$H$201,MATCH($A2&"-6",Matches!$J$2:$J$201,0))),5,IF(SIGN(N2-O2)<>SIGN(INDEX(Matches!$G$2:$G$201,MATCH($A2&"-6",Matches!$J$2:$J$201,0))-INDEX(Matches!$H$2:$H$201,MATCH($A2&"-6",Matches!$J$2:$J$201,0))),0,IF(N2-O2=INDEX(Matches!$G$2:$G$201,MATCH($A2&"-6",Matches!$J$2:$J$201,0))-INDEX(Matches!$H$2:$H$201,MATCH($A2&"-6",Matches!$J$2:$J$201,0)),3,2))))),"")) | AD2: =IF(OR($B2="",P2="",Q2=""),"",IFERROR(IF(OR(INDEX(Matches!$I$2:$I$201,MATCH($A2&"-7",Matches!$J$2:$J$201,0))="Void",INDEX(Matches!$G$2:$G$201,MATCH($A2&"-7",Matches!$J$2:$J$201,0))="",INDEX(Matches!$H$2:$H$201,MATCH($A2&"-7",Matches!$J$2:$J$201,0))=""),"",IF(AND($C2<>"",INDEX(Matches!$F$2:$F$201,MATCH($A2&"-7",Matches!$J$2:$J$201,0))<>"",$C2>=INDEX(Matches!$F$2:$F$201,MATCH($A2&"-7",Matches!$J$2:$J$201,0))),"",IF(AND(P2=INDEX(Matches!$G$2:$G$201,MATCH($A2&"-7",Matches!$J$2:$J$201,0)),Q2=INDEX(Matches!$H$2:$H$201,MATCH($A2&"-7",Matches!$J$2:$J$201,0))),5,IF(SIGN(P2-Q2)<>SIGN(INDEX(Matches!$G$2:$G$201,MATCH($A2&"-7",Matches!$J$2:$J$201,0))-INDEX(Matches!$H$2:$H$201,MATCH($A2&"-7",Matches!$J$2:$J$201,0))),0,IF(P2-Q2=INDEX(Matches!$G$2:$G$201,MATCH($A2&"-7",Matches!$J$2:$J$201,0))-INDEX(Matches!$H$2:$H$201,MATCH($A2&"-7",Matches!$J$2:$J$201,0)),3,2))))),"")) | AE2: =IF(OR($B2="",R2="",S2=""),"",IFERROR(IF(OR(INDEX(Matches!$I$2:$I$201,MATCH($A2&"-8",Matches!$J$2:$J$201,0))="Void",INDEX(Matches!$G$2:$G$201,MATCH($A2&"-8",Matches!$J$2:$J$201,0))="",INDEX(Matches!$H$2:$H$201,MATCH($A2&"-8",Matches!$J$2:$J$201,0))=""),"",IF(AND($C2<>"",INDEX(Matches!$F$2:$F$201,MATCH($A2&"-8",Matches!$J$2:$J$201,0))<>"",$C2>=INDEX(Matches!$F$2:$F$201,MATCH($A2&"-8",Matches!$J$2:$J$201,0))),"",IF(AND(R2=INDEX(Matches!$G$2:$G$201,MATCH($A2&"-8",Matches!$J$2:$J$201,0)),S2=INDEX(Matches!$H$2:$H$201,MATCH($A2&"-8",Matches!$J$2:$J$201,0))),5,IF(SIGN(R2-S2)<>SIGN(INDEX(Matches!$G$2:$G$201,MATCH($A2&"-8",Matches!$J$2:$J$201,0))-INDEX(Matches!$H$2:$H$201,MATCH($A2&"-8",Matches!$J$2:$J$201,0))),0,IF(R2-S2=INDEX(Matches!$G$2:$G$201,MATCH($A2&"-8",Matches!$J$2:$J$201,0))-INDEX(Matches!$H$2:$H$201,MATCH($A2&"-8",Matches!$J$2:$J$201,0)),3,2))))),"")) | AF2: =IF(OR($B2="",T2="",U2=""),"",IFERROR(IF(OR(INDEX(Matches!$I$2:$I$201,MATCH($A2&"-9",Matches!$J$2:$J$201,0))="Void",INDEX(Matches!$G$2:$G$201,MATCH($A2&"-9",Matches!$J$2:$J$201,0))="",INDEX(Matches!$H$2:$H$201,MATCH($A2&"-9",Matches!$J$2:$J$201,0))=""),"",IF(AND($C2<>"",INDEX(Matches!$F$2:$F$201,MATCH($A2&"-9",Matches!$J$2:$J$201,0))<>"",$C2>=INDEX(Matches!$F$2:$F$201,MATCH($A2&"-9",Matches!$J$2:$J$201,0))),"",IF(AND(T2=INDEX(Matches!$G$2:$G$201,MATCH($A2&"-9",Matches!$J$2:$J$201,0)),U2=INDEX(Matches!$H$2:$H$201,MATCH($A2&"-9",Matches!$J$2:$J$201,0))),5,IF(SIGN(T2-U2)<>SIGN(INDEX(Matches!$G$2:$G$201,MATCH($A2&"-9",Matches!$J$2:$J$201,0))-INDEX(Matches!$H$2:$H$201,MATCH($A2&"-9",Matches!$J$2:$J$201,0))),0,IF(T2-U2=INDEX(Matches!$G$2:$G$201,MATCH($A2&"-9",Matches!$J$2:$J$201,0))-INDEX(Matches!$H$2:$H$201,MATCH($A2&"-9",Matches!$J$2:$J$201,0)),3,2))))),"")) | AG2: =IF(OR($B2="",V2="",W2=""),"",IFERROR(IF(OR(INDEX(Matches!$I$2:$I$201,MATCH($A2&"-10",Matches!$J$2:$J$201,0))="Void",INDEX(Matches!$G$2:$G$201,MATCH($A2&"-10",Matches!$J$2:$J$201,0))="",INDEX(Matches!$H$2:$H$201,MATCH($A2&"-10",Matches!$J$2:$J$201,0))=""),"",IF(AND($C2<>"",INDEX(Matches!$F$2:$F$201,MATCH($A2&"-10",Matches!$J$2:$J$201,0))<>"",$C2>=INDEX(Matches!$F$2:$F$201,MATCH($A2&"-10",Matches!$J$2:$J$201,0))),"",IF(AND(V2=INDEX(Matches!$G$2:$G$201,MATCH($A2&"-10",Matches!$J$2:$J$201,0)),W2=INDEX(Matches!$H$2:$H$201,MATCH($A2&"-10",Matches!$J$2:$J$201,0))),5,IF(SIGN(V2-W2)<>SIGN(INDEX(Matches!$G$2:$G$201,MATCH($A2&"-10",Matches!$J$2:$J$201,0))-INDEX(Matches!$H$2:$H$201,MATCH($A2&"-10",Matches!$J$2:$J$201,0))),0,IF(V2-W2=INDEX(Matches!$G$2:$G$201,MATCH($A2&"-10",Matches!$J$2:$J$201,0))-INDEX(Matches!$H$2:$H$201,MATCH($A2&"-10",Matches!$J$2:$J$201,0)),3,2))))),"")) | AH2: =IF($B2="","",SUM(X2:AG2)) -> 5 | AI2: =IF($B2="","",COUNTIF(X2:AG2,5)) -> 1 | AJ2: =IF($B2="","",COUNTIF(X2:AG2,">=2")) -> 1 | AK2: =IF($B2="","",COUNT(X2:AG2)) -> 3
A3: 1 | B3: Example – Khalid | C3: 46296.861 | D3: 0 | E3: 2 | F3: 1 | G3: 1 | H3: 1 | I3: 2 | X3: =IF(OR($B3="",D3="",E3=""),"",IFERROR(IF(OR(INDEX(Matches!$I$2:$I$201,MATCH($A3&"-1",Matches!$J$2:$J$201,0))="Void",INDEX(Matches!$G$2:$G$201,MATCH($A3&"-1",Matches!$J$2:$J$201,0))="",INDEX(Matches!$H$2:$H$201,MATCH($A3&"-1",Matches!$J$2:$J$201,0))=""),"",IF(AND($C3<>"",INDEX(Matches!$F$2:$F$201,MATCH($A3&"-1",Matches!$J$2:$J$201,0))<>"",$C3>=INDEX(Matches!$F$2:$F$201,MATCH($A3&"-1",Matches!$J$2:$J$201,0))),"",IF(AND(D3=INDEX(Matches!$G$2:$G$201,MATCH($A3&"-1",Matches!$J$2:$J$201,0)),E3=INDEX(Matches!$H$2:$H$201,MATCH($A3&"-1",Matches!$J$2:$J$201,0))),5,IF(SIGN(D3-E3)<>SIGN(INDEX(Matches!$G$2:$G$201,MATCH($A3&"-1",Matches!$J$2:$J$201,0))-INDEX(Matches!$H$2:$H$201,MATCH($A3&"-1",Matches!$J$2:$J$201,0))),0,IF(D3-E3=INDEX(Matches!$G$2:$G$201,MATCH($A3&"-1",Matches!$J$2:$J$201,0))-INDEX(Matches!$H$2:$H$201,MATCH($A3&"-1",Matches!$J$2:$J$201,0)),3,2))))),"")) -> 0 | Y3: =IF(OR($B3="",F3="",G3=""),"",IFERROR(IF(OR(INDEX(Matches!$I$2:$I$201,MATCH($A3&"-2",Matches!$J$2:$J$201,0))="Void",INDEX(Matches!$G$2:$G$201,MATCH($A3&"-2",Matches!$J$2:$J$201,0))="",INDEX(Matches!$H$2:$H$201,MATCH($A3&"-2",Matches!$J$2:$J$201,0))=""),"",IF(AND($C3<>"",INDEX(Matches!$F$2:$F$201,MATCH($A3&"-2",Matches!$J$2:$J$201,0))<>"",$C3>=INDEX(Matches!$F$2:$F$201,MATCH($A3&"-2",Matches!$J$2:$J$201,0))),"",IF(AND(F3=INDEX(Matches!$G$2:$G$201,MATCH($A3&"-2",Matches!$J$2:$J$201,0)),G3=INDEX(Matches!$H$2:$H$201,MATCH($A3&"-2",Matches!$J$2:$J$201,0))),5,IF(SIGN(F3-G3)<>SIGN(INDEX(Matches!$G$2:$G$201,MATCH($A3&"-2",Matches!$J$2:$J$201,0))-INDEX(Matches!$H$2:$H$201,MATCH($A3&"-2",Matches!$J$2:$J$201,0))),0,IF(F3-G3=INDEX(Matches!$G$2:$G$201,MATCH($A3&"-2",Matches!$J$2:$J$201,0))-INDEX(Matches!$H$2:$H$201,MATCH($A3&"-2",Matches!$J$2:$J$201,0)),3,2))))),"")) -> 5 | Z3: =IF(OR($B3="",H3="",I3=""),"",IFERROR(IF(OR(INDEX(Matches!$I$2:$I$201,MATCH($A3&"-3",Matches!$J$2:$J$201,0))="Void",INDEX(Matches!$G$2:$G$201,MATCH($A3&"-3",Matches!$J$2:$J$201,0))="",INDEX(Matches!$H$2:$H$201,MATCH($A3&"-3",Matches!$J$2:$J$201,0))=""),"",IF(AND($C3<>"",INDEX(Matches!$F$2:$F$201,MATCH($A3&"-3",Matches!$J$2:$J$201,0))<>"",$C3>=INDEX(Matches!$F$2:$F$201,MATCH($A3&"-3",Matches!$J$2:$J$201,0))),"",IF(AND(H3=INDEX(Matches!$G$2:$G$201,MATCH($A3&"-3",Matches!$J$2:$J$201,0)),I3=INDEX(Matches!$H$2:$H$201,MATCH($A3&"-3",Matches!$J$2:$J$201,0))),5,IF(SIGN(H3-I3)<>SIGN(INDEX(Matches!$G$2:$G$201,MATCH($A3&"-3",Matches!$J$2:$J$201,0))-INDEX(Matches!$H$2:$H$201,MATCH($A3&"-3",Matches!$J$2:$J$201,0))),0,IF(H3-I3=INDEX(Matches!$G$2:$G$201,MATCH($A3&"-3",Matches!$J$2:$J$201,0))-INDEX(Matches!$H$2:$H$201,MATCH($A3&"-3",Matches!$J$2:$J$201,0)),3,2))))),"")) -> 2 | AA3: =IF(OR($B3="",J3="",K3=""),"",IFERROR(IF(OR(INDEX(Matches!$I$2:$I$201,MATCH($A3&"-4",Matches!$J$2:$J$201,0))="Void",INDEX(Matches!$G$2:$G$201,MATCH($A3&"-4",Matches!$J$2:$J$201,0))="",INDEX(Matches!$H$2:$H$201,MATCH($A3&"-4",Matches!$J$2:$J$201,0))=""),"",IF(AND($C3<>"",INDEX(Matches!$F$2:$F$201,MATCH($A3&"-4",Matches!$J$2:$J$201,0))<>"",$C3>=INDEX(Matches!$F$2:$F$201,MATCH($A3&"-4",Matches!$J$2:$J$201,0))),"",IF(AND(J3=INDEX(Matches!$G$2:$G$201,MATCH($A3&"-4",Matches!$J$2:$J$201,0)),K3=INDEX(Matches!$H$2:$H$201,MATCH($A3&"-4",Matches!$J$2:$J$201,0))),5,IF(SIGN(J3-K3)<>SIGN(INDEX(Matches!$G$2:$G$201,MATCH($A3&"-4",Matches!$J$2:$J$201,0))-INDEX(Matches!$H$2:$H$201,MATCH($A3&"-4",Matches!$J$2:$J$201,0))),0,IF(J3-K3=INDEX(Matches!$G$2:$G$201,MATCH($A3&"-4",Matches!$J$2:$J$201,0))-INDEX(Matches!$H$2:$H$201,MATCH($A3&"-4",Matches!$J$2:$J$201,0)),3,2))))),"")) | AB3: =IF(OR($B3="",L3="",M3=""),"",IFERROR(IF(OR(INDEX(Matches!$I$2:$I$201,MATCH($A3&"-5",Matches!$J$2:$J$201,0))="Void",INDEX(Matches!$G$2:$G$201,MATCH($A3&"-5",Matches!$J$2:$J$201,0))="",INDEX(Matches!$H$2:$H$201,MATCH($A3&"-5",Matches!$J$2:$J$201,0))=""),"",IF(AND($C3<>"",INDEX(Matches!$F$2:$F$201,MATCH($A3&"-5",Matches!$J$2:$J$201,0))<>"",$C3>=INDEX(Matches!$F$2:$F$201,MATCH($A3&"-5",Matches!$J$2:$J$201,0))),"",IF(AND(L3=INDEX(Matches!$G$2:$G$201,MATCH($A3&"-5",Matches!$J$2:$J$201,0)),M3=INDEX(Matches!$H$2:$H$201,MATCH($A3&"-5",Matches!$J$2:$J$201,0))),5,IF(SIGN(L3-M3)<>SIGN(INDEX(Matches!$G$2:$G$201,MATCH($A3&"-5",Matches!$J$2:$J$201,0))-INDEX(Matches!$H$2:$H$201,MATCH($A3&"-5",Matches!$J$2:$J$201,0))),0,IF(L3-M3=INDEX(Matches!$G$2:$G$201,MATCH($A3&"-5",Matches!$J$2:$J$201,0))-INDEX(Matches!$H$2:$H$201,MATCH($A3&"-5",Matches!$J$2:$J$201,0)),3,2))))),"")) | AC3: =IF(OR($B3="",N3="",O3=""),"",IFERROR(IF(OR(INDEX(Matches!$I$2:$I$201,MATCH($A3&"-6",Matches!$J$2:$J$201,0))="Void",INDEX(Matches!$G$2:$G$201,MATCH($A3&"-6",Matches!$J$2:$J$201,0))="",INDEX(Matches!$H$2:$H$201,MATCH($A3&"-6",Matches!$J$2:$J$201,0))=""),"",IF(AND($C3<>"",INDEX(Matches!$F$2:$F$201,MATCH($A3&"-6",Matches!$J$2:$J$201,0))<>"",$C3>=INDEX(Matches!$F$2:$F$201,MATCH($A3&"-6",Matches!$J$2:$J$201,0))),"",IF(AND(N3=INDEX(Matches!$G$2:$G$201,MATCH($A3&"-6",Matches!$J$2:$J$201,0)),O3=INDEX(Matches!$H$2:$H$201,MATCH($A3&"-6",Matches!$J$2:$J$201,0))),5,IF(SIGN(N3-O3)<>SIGN(INDEX(Matches!$G$2:$G$201,MATCH($A3&"-6",Matches!$J$2:$J$201,0))-INDEX(Matches!$H$2:$H$201,MATCH($A3&"-6",Matches!$J$2:$J$201,0))),0,IF(N3-O3=INDEX(Matches!$G$2:$G$201,MATCH($A3&"-6",Matches!$J$2:$J$201,0))-INDEX(Matches!$H$2:$H$201,MATCH($A3&"-6",Matches!$J$2:$J$201,0)),3,2))))),"")) | AD3: =IF(OR($B3="",P3="",Q3=""),"",IFERROR(IF(OR(INDEX(Matches!$I$2:$I$201,MATCH($A3&"-7",Matches!$J$2:$J$201,0))="Void",INDEX(Matches!$G$2:$G$201,MATCH($A3&"-7",Matches!$J$2:$J$201,0))="",INDEX(Matches!$H$2:$H$201,MATCH($A3&"-7",Matches!$J$2:$J$201,0))=""),"",IF(AND($C3<>"",INDEX(Matches!$F$2:$F$201,MATCH($A3&"-7",Matches!$J$2:$J$201,0))<>"",$C3>=INDEX(Matches!$F$2:$F$201,MATCH($A3&"-7",Matches!$J$2:$J$201,0))),"",IF(AND(P3=INDEX(Matches!$G$2:$G$201,MATCH($A3&"-7",Matches!$J$2:$J$201,0)),Q3=INDEX(Matches!$H$2:$H$201,MATCH($A3&"-7",Matches!$J$2:$J$201,0))),5,IF(SIGN(P3-Q3)<>SIGN(INDEX(Matches!$G$2:$G$201,MATCH($A3&"-7",Matches!$J$2:$J$201,0))-INDEX(Matches!$H$2:$H$201,MATCH($A3&"-7",Matches!$J$2:$J$201,0))),0,IF(P3-Q3=INDEX(Matches!$G$2:$G$201,MATCH($A3&"-7",Matches!$J$2:$J$201,0))-INDEX(Matches!$H$2:$H$201,MATCH($A3&"-7",Matches!$J$2:$J$201,0)),3,2))))),"")) | AE3: =IF(OR($B3="",R3="",S3=""),"",IFERROR(IF(OR(INDEX(Matches!$I$2:$I$201,MATCH($A3&"-8",Matches!$J$2:$J$201,0))="Void",INDEX(Matches!$G$2:$G$201,MATCH($A3&"-8",Matches!$J$2:$J$201,0))="",INDEX(Matches!$H$2:$H$201,MATCH($A3&"-8",Matches!$J$2:$J$201,0))=""),"",IF(AND($C3<>"",INDEX(Matches!$F$2:$F$201,MATCH($A3&"-8",Matches!$J$2:$J$201,0))<>"",$C3>=INDEX(Matches!$F$2:$F$201,MATCH($A3&"-8",Matches!$J$2:$J$201,0))),"",IF(AND(R3=INDEX(Matches!$G$2:$G$201,MATCH($A3&"-8",Matches!$J$2:$J$201,0)),S3=INDEX(Matches!$H$2:$H$201,MATCH($A3&"-8",Matches!$J$2:$J$201,0))),5,IF(SIGN(R3-S3)<>SIGN(INDEX(Matches!$G$2:$G$201,MATCH($A3&"-8",Matches!$J$2:$J$201,0))-INDEX(Matches!$H$2:$H$201,MATCH($A3&"-8",Matches!$J$2:$J$201,0))),0,IF(R3-S3=INDEX(Matches!$G$2:$G$201,MATCH($A3&"-8",Matches!$J$2:$J$201,0))-INDEX(Matches!$H$2:$H$201,MATCH($A3&"-8",Matches!$J$2:$J$201,0)),3,2))))),"")) | AF3: =IF(OR($B3="",T3="",U3=""),"",IFERROR(IF(OR(INDEX(Matches!$I$2:$I$201,MATCH($A3&"-9",Matches!$J$2:$J$201,0))="Void",INDEX(Matches!$G$2:$G$201,MATCH($A3&"-9",Matches!$J$2:$J$201,0))="",INDEX(Matches!$H$2:$H$201,MATCH($A3&"-9",Matches!$J$2:$J$201,0))=""),"",IF(AND($C3<>"",INDEX(Matches!$F$2:$F$201,MATCH($A3&"-9",Matches!$J$2:$J$201,0))<>"",$C3>=INDEX(Matches!$F$2:$F$201,MATCH($A3&"-9",Matches!$J$2:$J$201,0))),"",IF(AND(T3=INDEX(Matches!$G$2:$G$201,MATCH($A3&"-9",Matches!$J$2:$J$201,0)),U3=INDEX(Matches!$H$2:$H$201,MATCH($A3&"-9",Matches!$J$2:$J$201,0))),5,IF(SIGN(T3-U3)<>SIGN(INDEX(Matches!$G$2:$G$201,MATCH($A3&"-9",Matches!$J$2:$J$201,0))-INDEX(Matches!$H$2:$H$201,MATCH($A3&"-9",Matches!$J$2:$J$201,0))),0,IF(T3-U3=INDEX(Matches!$G$2:$G$201,MATCH($A3&"-9",Matches!$J$2:$J$201,0))-INDEX(Matches!$H$2:$H$201,MATCH($A3&"-9",Matches!$J$2:$J$201,0)),3,2))))),"")) | AG3: =IF(OR($B3="",V3="",W3=""),"",IFERROR(IF(OR(INDEX(Matches!$I$2:$I$201,MATCH($A3&"-10",Matches!$J$2:$J$201,0))="Void",INDEX(Matches!$G$2:$G$201,MATCH($A3&"-10",Matches!$J$2:$J$201,0))="",INDEX(Matches!$H$2:$H$201,MATCH($A3&"-10",Matches!$J$2:$J$201,0))=""),"",IF(AND($C3<>"",INDEX(Matches!$F$2:$F$201,MATCH($A3&"-10",Matches!$J$2:$J$201,0))<>"",$C3>=INDEX(Matches!$F$2:$F$201,MATCH($A3&"-10",Matches!$J$2:$J$201,0))),"",IF(AND(V3=INDEX(Matches!$G$2:$G$201,MATCH($A3&"-10",Matches!$J$2:$J$201,0)),W3=INDEX(Matches!$H$2:$H$201,MATCH($A3&"-10",Matches!$J$2:$J$201,0))),5,IF(SIGN(V3-W3)<>SIGN(INDEX(Matches!$G$2:$G$201,MATCH($A3&"-10",Matches!$J$2:$J$201,0))-INDEX(Matches!$H$2:$H$201,MATCH($A3&"-10",Matches!$J$2:$J$201,0))),0,IF(V3-W3=INDEX(Matches!$G$2:$G$201,MATCH($A3&"-10",Matches!$J$2:$J$201,0))-INDEX(Matches!$H$2:$H$201,MATCH($A3&"-10",Matches!$J$2:$J$201,0)),3,2))))),"")) | AH3: =IF($B3="","",SUM(X3:AG3)) -> 7 | AI3: =IF($B3="","",COUNTIF(X3:AG3,5)) -> 1 | AJ3: =IF($B3="","",COUNTIF(X3:AG3,">=2")) -> 2 | AK3: =IF($B3="","",COUNT(X3:AG3)) -> 3
A4: 1 | B4: Example – Omar | C4: 46297.5 | D4: 3 | E4: 1 | F4: 2 | G4: 2 | H4: 0 | I4: 1 | X4: =IF(OR($B4="",D4="",E4=""),"",IFERROR(IF(OR(INDEX(Matches!$I$2:$I$201,MATCH($A4&"-1",Matches!$J$2:$J$201,0))="Void",INDEX(Matches!$G$2:$G$201,MATCH($A4&"-1",Matches!$J$2:$J$201,0))="",INDEX(Matches!$H$2:$H$201,MATCH($A4&"-1",Matches!$J$2:$J$201,0))=""),"",IF(AND($C4<>"",INDEX(Matches!$F$2:$F$201,MATCH($A4&"-1",Matches!$J$2:$J$201,0))<>"",$C4>=INDEX(Matches!$F$2:$F$201,MATCH($A4&"-1",Matches!$J$2:$J$201,0))),"",IF(AND(D4=INDEX(Matches!$G$2:$G$201,MATCH($A4&"-1",Matches!$J$2:$J$201,0)),E4=INDEX(Matches!$H$2:$H$201,MATCH($A4&"-1",Matches!$J$2:$J$201,0))),5,IF(SIGN(D4-E4)<>SIGN(INDEX(Matches!$G$2:$G$201,MATCH($A4&"-1",Matches!$J$2:$J$201,0))-INDEX(Matches!$H$2:$H$201,MATCH($A4&"-1",Matches!$J$2:$J$201,0))),0,IF(D4-E4=INDEX(Matches!$G$2:$G$201,MATCH($A4&"-1",Matches!$J$2:$J$201,0))-INDEX(Matches!$H$2:$H$201,MATCH($A4&"-1",Matches!$J$2:$J$201,0)),3,2))))),"")) -> 2 | Y4: =IF(OR($B4="",F4="",G4=""),"",IFERROR(IF(OR(INDEX(Matches!$I$2:$I$201,MATCH($A4&"-2",Matches!$J$2:$J$201,0))="Void",INDEX(Matches!$G$2:$G$201,MATCH($A4&"-2",Matches!$J$2:$J$201,0))="",INDEX(Matches!$H$2:$H$201,MATCH($A4&"-2",Matches!$J$2:$J$201,0))=""),"",IF(AND($C4<>"",INDEX(Matches!$F$2:$F$201,MATCH($A4&"-2",Matches!$J$2:$J$201,0))<>"",$C4>=INDEX(Matches!$F$2:$F$201,MATCH($A4&"-2",Matches!$J$2:$J$201,0))),"",IF(AND(F4=INDEX(Matches!$G$2:$G$201,MATCH($A4&"-2",Matches!$J$2:$J$201,0)),G4=INDEX(Matches!$H$2:$H$201,MATCH($A4&"-2",Matches!$J$2:$J$201,0))),5,IF(SIGN(F4-G4)<>SIGN(INDEX(Matches!$G$2:$G$201,MATCH($A4&"-2",Matches!$J$2:$J$201,0))-INDEX(Matches!$H$2:$H$201,MATCH($A4&"-2",Matches!$J$2:$J$201,0))),0,IF(F4-G4=INDEX(Matches!$G$2:$G$201,MATCH($A4&"-2",Matches!$J$2:$J$201,0))-INDEX(Matches!$H$2:$H$201,MATCH($A4&"-2",Matches!$J$2:$J$201,0)),3,2))))),"")) -> 3 | Z4: =IF(OR($B4="",H4="",I4=""),"",IFERROR(IF(OR(INDEX(Matches!$I$2:$I$201,MATCH($A4&"-3",Matches!$J$2:$J$201,0))="Void",INDEX(Matches!$G$2:$G$201,MATCH($A4&"-3",Matches!$J$2:$J$201,0))="",INDEX(Matches!$H$2:$H$201,MATCH($A4&"-3",Matches!$J$2:$J$201,0))=""),"",IF(AND($C4<>"",INDEX(Matches!$F$2:$F$201,MATCH($A4&"-3",Matches!$J$2:$J$201,0))<>"",$C4>=INDEX(Matches!$F$2:$F$201,MATCH($A4&"-3",Matches!$J$2:$J$201,0))),"",IF(AND(H4=INDEX(Matches!$G$2:$G$201,MATCH($A4&"-3",Matches!$J$2:$J$201,0)),I4=INDEX(Matches!$H$2:$H$201,MATCH($A4&"-3",Matches!$J$2:$J$201,0))),5,IF(SIGN(H4-I4)<>SIGN(INDEX(Matches!$G$2:$G$201,MATCH($A4&"-3",Matches!$J$2:$J$201,0))-INDEX(Matches!$H$2:$H$201,MATCH($A4&"-3",Matches!$J$2:$J$201,0))),0,IF(H4-I4=INDEX(Matches!$G$2:$G$201,MATCH($A4&"-3",Matches!$J$2:$J$201,0))-INDEX(Matches!$H$2:$H$201,MATCH($A4&"-3",Matches!$J$2:$J$201,0)),3,2))))),"")) -> 2 | AA4: =IF(OR($B4="",J4="",K4=""),"",IFERROR(IF(OR(INDEX(Matches!$I$2:$I$201,MATCH($A4&"-4",Matches!$J$2:$J$201,0))="Void",INDEX(Matches!$G$2:$G$201,MATCH($A4&"-4",Matches!$J$2:$J$201,0))="",INDEX(Matches!$H$2:$H$201,MATCH($A4&"-4",Matches!$J$2:$J$201,0))=""),"",IF(AND($C4<>"",INDEX(Matches!$F$2:$F$201,MATCH($A4&"-4",Matches!$J$2:$J$201,0))<>"",$C4>=INDEX(Matches!$F$2:$F$201,MATCH($A4&"-4",Matches!$J$2:$J$201,0))),"",IF(AND(J4=INDEX(Matches!$G$2:$G$201,MATCH($A4&"-4",Matches!$J$2:$J$201,0)),K4=INDEX(Matches!$H$2:$H$201,MATCH($A4&"-4",Matches!$J$2:$J$201,0))),5,IF(SIGN(J4-K4)<>SIGN(INDEX(Matches!$G$2:$G$201,MATCH($A4&"-4",Matches!$J$2:$J$201,0))-INDEX(Matches!$H$2:$H$201,MATCH($A4&"-4",Matches!$J$2:$J$201,0))),0,IF(J4-K4=INDEX(Matches!$G$2:$G$201,MATCH($A4&"-4",Matches!$J$2:$J$201,0))-INDEX(Matches!$H$2:$H$201,MATCH($A4&"-4",Matches!$J$2:$J$201,0)),3,2))))),"")) | AB4: =IF(OR($B4="",L4="",M4=""),"",IFERROR(IF(OR(INDEX(Matches!$I$2:$I$201,MATCH($A4&"-5",Matches!$J$2:$J$201,0))="Void",INDEX(Matches!$G$2:$G$201,MATCH($A4&"-5",Matches!$J$2:$J$201,0))="",INDEX(Matches!$H$2:$H$201,MATCH($A4&"-5",Matches!$J$2:$J$201,0))=""),"",IF(AND($C4<>"",INDEX(Matches!$F$2:$F$201,MATCH($A4&"-5",Matches!$J$2:$J$201,0))<>"",$C4>=INDEX(Matches!$F$2:$F$201,MATCH($A4&"-5",Matches!$J$2:$J$201,0))),"",IF(AND(L4=INDEX(Matches!$G$2:$G$201,MATCH($A4&"-5",Matches!$J$2:$J$201,0)),M4=INDEX(Matches!$H$2:$H$201,MATCH($A4&"-5",Matches!$J$2:$J$201,0))),5,IF(SIGN(L4-M4)<>SIGN(INDEX(Matches!$G$2:$G$201,MATCH($A4&"-5",Matches!$J$2:$J$201,0))-INDEX(Matches!$H$2:$H$201,MATCH($A4&"-5",Matches!$J$2:$J$201,0))),0,IF(L4-M4=INDEX(Matches!$G$2:$G$201,MATCH($A4&"-5",Matches!$J$2:$J$201,0))-INDEX(Matches!$H$2:$H$201,MATCH($A4&"-5",Matches!$J$2:$J$201,0)),3,2))))),"")) | AC4: =IF(OR($B4="",N4="",O4=""),"",IFERROR(IF(OR(INDEX(Matches!$I$2:$I$201,MATCH($A4&"-6",Matches!$J$2:$J$201,0))="Void",INDEX(Matches!$G$2:$G$201,MATCH($A4&"-6",Matches!$J$2:$J$201,0))="",INDEX(Matches!$H$2:$H$201,MATCH($A4&"-6",Matches!$J$2:$J$201,0))=""),"",IF(AND($C4<>"",INDEX(Matches!$F$2:$F$201,MATCH($A4&"-6",Matches!$J$2:$J$201,0))<>"",$C4>=INDEX(Matches!$F$2:$F$201,MATCH($A4&"-6",Matches!$J$2:$J$201,0))),"",IF(AND(N4=INDEX(Matches!$G$2:$G$201,MATCH($A4&"-6",Matches!$J$2:$J$201,0)),O4=INDEX(Matches!$H$2:$H$201,MATCH($A4&"-6",Matches!$J$2:$J$201,0))),5,IF(SIGN(N4-O4)<>SIGN(INDEX(Matches!$G$2:$G$201,MATCH($A4&"-6",Matches!$J$2:$J$201,0))-INDEX(Matches!$H$2:$H$201,MATCH($A4&"-6",Matches!$J$2:$J$201,0))),0,IF(N4-O4=INDEX(Matches!$G$2:$G$201,MATCH($A4&"-6",Matches!$J$2:$J$201,0))-INDEX(Matches!$H$2:$H$201,MATCH($A4&"-6",Matches!$J$2:$J$201,0)),3,2))))),"")) | AD4: =IF(OR($B4="",P4="",Q4=""),"",IFERROR(IF(OR(INDEX(Matches!$I$2:$I$201,MATCH($A4&"-7",Matches!$J$2:$J$201,0))="Void",INDEX(Matches!$G$2:$G$201,MATCH($A4&"-7",Matches!$J$2:$J$201,0))="",INDEX(Matches!$H$2:$H$201,MATCH($A4&"-7",Matches!$J$2:$J$201,0))=""),"",IF(AND($C4<>"",INDEX(Matches!$F$2:$F$201,MATCH($A4&"-7",Matches!$J$2:$J$201,0))<>"",$C4>=INDEX(Matches!$F$2:$F$201,MATCH($A4&"-7",Matches!$J$2:$J$201,0))),"",IF(AND(P4=INDEX(Matches!$G$2:$G$201,MATCH($A4&"-7",Matches!$J$2:$J$201,0)),Q4=INDEX(Matches!$H$2:$H$201,MATCH($A4&"-7",Matches!$J$2:$J$201,0))),5,IF(SIGN(P4-Q4)<>SIGN(INDEX(Matches!$G$2:$G$201,MATCH($A4&"-7",Matches!$J$2:$J$201,0))-INDEX(Matches!$H$2:$H$201,MATCH($A4&"-7",Matches!$J$2:$J$201,0))),0,IF(P4-Q4=INDEX(Matches!$G$2:$G$201,MATCH($A4&"-7",Matches!$J$2:$J$201,0))-INDEX(Matches!$H$2:$H$201,MATCH($A4&"-7",Matches!$J$2:$J$201,0)),3,2))))),"")) | AE4: =IF(OR($B4="",R4="",S4=""),"",IFERROR(IF(OR(INDEX(Matches!$I$2:$I$201,MATCH($A4&"-8",Matches!$J$2:$J$201,0))="Void",INDEX(Matches!$G$2:$G$201,MATCH($A4&"-8",Matches!$J$2:$J$201,0))="",INDEX(Matches!$H$2:$H$201,MATCH($A4&"-8",Matches!$J$2:$J$201,0))=""),"",IF(AND($C4<>"",INDEX(Matches!$F$2:$F$201,MATCH($A4&"-8",Matches!$J$2:$J$201,0))<>"",$C4>=INDEX(Matches!$F$2:$F$201,MATCH($A4&"-8",Matches!$J$2:$J$201,0))),"",IF(AND(R4=INDEX(Matches!$G$2:$G$201,MATCH($A4&"-8",Matches!$J$2:$J$201,0)),S4=INDEX(Matches!$H$2:$H$201,MATCH($A4&"-8",Matches!$J$2:$J$201,0))),5,IF(SIGN(R4-S4)<>SIGN(INDEX(Matches!$G$2:$G$201,MATCH($A4&"-8",Matches!$J$2:$J$201,0))-INDEX(Matches!$H$2:$H$201,MATCH($A4&"-8",Matches!$J$2:$J$201,0))),0,IF(R4-S4=INDEX(Matches!$G$2:$G$201,MATCH($A4&"-8",Matches!$J$2:$J$201,0))-INDEX(Matches!$H$2:$H$201,MATCH($A4&"-8",Matches!$J$2:$J$201,0)),3,2))))),"")) | AF4: =IF(OR($B4="",T4="",U4=""),"",IFERROR(IF(OR(INDEX(Matches!$I$2:$I$201,MATCH($A4&"-9",Matches!$J$2:$J$201,0))="Void",INDEX(Matches!$G$2:$G$201,MATCH($A4&"-9",Matches!$J$2:$J$201,0))="",INDEX(Matches!$H$2:$H$201,MATCH($A4&"-9",Matches!$J$2:$J$201,0))=""),"",IF(AND($C4<>"",INDEX(Matches!$F$2:$F$201,MATCH($A4&"-9",Matches!$J$2:$J$201,0))<>"",$C4>=INDEX(Matches!$F$2:$F$201,MATCH($A4&"-9",Matches!$J$2:$J$201,0))),"",IF(AND(T4=INDEX(Matches!$G$2:$G$201,MATCH($A4&"-9",Matches!$J$2:$J$201,0)),U4=INDEX(Matches!$H$2:$H$201,MATCH($A4&"-9",Matches!$J$2:$J$201,0))),5,IF(SIGN(T4-U4)<>SIGN(INDEX(Matches!$G$2:$G$201,MATCH($A4&"-9",Matches!$J$2:$J$201,0))-INDEX(Matches!$H$2:$H$201,MATCH($A4&"-9",Matches!$J$2:$J$201,0))),0,IF(T4-U4=INDEX(Matches!$G$2:$G$201,MATCH($A4&"-9",Matches!$J$2:$J$201,0))-INDEX(Matches!$H$2:$H$201,MATCH($A4&"-9",Matches!$J$2:$J$201,0)),3,2))))),"")) | AG4: =IF(OR($B4="",V4="",W4=""),"",IFERROR(IF(OR(INDEX(Matches!$I$2:$I$201,MATCH($A4&"-10",Matches!$J$2:$J$201,0))="Void",INDEX(Matches!$G$2:$G$201,MATCH($A4&"-10",Matches!$J$2:$J$201,0))="",INDEX(Matches!$H$2:$H$201,MATCH($A4&"-10",Matches!$J$2:$J$201,0))=""),"",IF(AND($C4<>"",INDEX(Matches!$F$2:$F$201,MATCH($A4&"-10",Matches!$J$2:$J$201,0))<>"",$C4>=INDEX(Matches!$F$2:$F$201,MATCH($A4&"-10",Matches!$J$2:$J$201,0))),"",IF(AND(V4=INDEX(Matches!$G$2:$G$201,MATCH($A4&"-10",Matches!$J$2:$J$201,0)),W4=INDEX(Matches!$H$2:$H$201,MATCH($A4&"-10",Matches!$J$2:$J$201,0))),5,IF(SIGN(V4-W4)<>SIGN(INDEX(Matches!$G$2:$G$201,MATCH($A4&"-10",Matches!$J$2:$J$201,0))-INDEX(Matches!$H$2:$H$201,MATCH($A4&"-10",Matches!$J$2:$J$201,0))),0,IF(V4-W4=INDEX(Matches!$G$2:$G$201,MATCH($A4&"-10",Matches!$J$2:$J$201,0))-INDEX(Matches!$H$2:$H$201,MATCH($A4&"-10",Matches!$J$2:$J$201,0)),3,2))))),"")) | AH4: =IF($B4="","",SUM(X4:AG4)) -> 7 | AI4: =IF($B4="","",COUNTIF(X4:AG4,5)) -> 0 | AJ4: =IF($B4="","",COUNTIF(X4:AG4,">=2")) -> 3 | AK4: =IF($B4="","",COUNT(X4:AG4)) -> 3
X5: =IF(OR($B5="",D5="",E5=""),"",IFERROR(IF(OR(INDEX(Matches!$I$2:$I$201,MATCH($A5&"-1",Matches!$J$2:$J$201,0))="Void",INDEX(Matches!$G$2:$G$201,MATCH($A5&"-1",Matches!$J$2:$J$201,0))="",INDEX(Matches!$H$2:$H$201,MATCH($A5&"-1",Matches!$J$2:$J$201,0))=""),"",IF(AND($C5<>"",INDEX(Matches!$F$2:$F$201,MATCH($A5&"-1",Matches!$J$2:$J$201,0))<>"",$C5>=INDEX(Matches!$F$2:$F$201,MATCH($A5&"-1",Matches!$J$2:$J$201,0))),"",IF(AND(D5=INDEX(Matches!$G$2:$G$201,MATCH($A5&"-1",Matches!$J$2:$J$201,0)),E5=INDEX(Matches!$H$2:$H$201,MATCH($A5&"-1",Matches!$J$2:$J$201,0))),5,IF(SIGN(D5-E5)<>SIGN(INDEX(Matches!$G$2:$G$201,MATCH($A5&"-1",Matches!$J$2:$J$201,0))-INDEX(Matches!$H$2:$H$201,MATCH($A5&"-1",Matches!$J$2:$J$201,0))),0,IF(D5-E5=INDEX(Matches!$G$2:$G$201,MATCH($A5&"-1",Matches!$J$2:$J$201,0))-INDEX(Matches!$H$2:$H$201,MATCH($A5&"-1",Matches!$J$2:$J$201,0)),3,2))))),"")) | Y5: =IF(OR($B5="",F5="",G5=""),"",IFERROR(IF(OR(INDEX(Matches!$I$2:$I$201,MATCH($A5&"-2",Matches!$J$2:$J$201,0))="Void",INDEX(Matches!$G$2:$G$201,MATCH($A5&"-2",Matches!$J$2:$J$201,0))="",INDEX(Matches!$H$2:$H$201,MATCH($A5&"-2",Matches!$J$2:$J$201,0))=""),"",IF(AND($C5<>"",INDEX(Matches!$F$2:$F$201,MATCH($A5&"-2",Matches!$J$2:$J$201,0))<>"",$C5>=INDEX(Matches!$F$2:$F$201,MATCH($A5&"-2",Matches!$J$2:$J$201,0))),"",IF(AND(F5=INDEX(Matches!$G$2:$G$201,MATCH($A5&"-2",Matches!$J$2:$J$201,0)),G5=INDEX(Matches!$H$2:$H$201,MATCH($A5&"-2",Matches!$J$2:$J$201,0))),5,IF(SIGN(F5-G5)<>SIGN(INDEX(Matches!$G$2:$G$201,MATCH($A5&"-2",Matches!$J$2:$J$201,0))-INDEX(Matches!$H$2:$H$201,MATCH($A5&"-2",Matches!$J$2:$J$201,0))),0,IF(F5-G5=INDEX(Matches!$G$2:$G$201,MATCH($A5&"-2",Matches!$J$2:$J$201,0))-INDEX(Matches!$H$2:$H$201,MATCH($A5&"-2",Matches!$J$2:$J$201,0)),3,2))))),"")) | Z5: =IF(OR($B5="",H5="",I5=""),"",IFERROR(IF(OR(INDEX(Matches!$I$2:$I$201,MATCH($A5&"-3",Matches!$J$2:$J$201,0))="Void",INDEX(Matches!$G$2:$G$201,MATCH($A5&"-3",Matches!$J$2:$J$201,0))="",INDEX(Matches!$H$2:$H$201,MATCH($A5&"-3",Matches!$J$2:$J$201,0))=""),"",IF(AND($C5<>"",INDEX(Matches!$F$2:$F$201,MATCH($A5&"-3",Matches!$J$2:$J$201,0))<>"",$C5>=INDEX(Matches!$F$2:$F$201,MATCH($A5&"-3",Matches!$J$2:$J$201,0))),"",IF(AND(H5=INDEX(Matches!$G$2:$G$201,MATCH($A5&"-3",Matches!$J$2:$J$201,0)),I5=INDEX(Matches!$H$2:$H$201,MATCH($A5&"-3",Matches!$J$2:$J$201,0))),5,IF(SIGN(H5-I5)<>SIGN(INDEX(Matches!$G$2:$G$201,MATCH($A5&"-3",Matches!$J$2:$J$201,0))-INDEX(Matches!$H$2:$H$201,MATCH($A5&"-3",Matches!$J$2:$J$201,0))),0,IF(H5-I5=INDEX(Matches!$G$2:$G$201,MATCH($A5&"-3",Matches!$J$2:$J$201,0))-INDEX(Matches!$H$2:$H$201,MATCH($A5&"-3",Matches!$J$2:$J$201,0)),3,2))))),"")) | AA5: =IF(OR($B5="",J5="",K5=""),"",IFERROR(IF(OR(INDEX(Matches!$I$2:$I$201,MATCH($A5&"-4",Matches!$J$2:$J$201,0))="Void",INDEX(Matches!$G$2:$G$201,MATCH($A5&"-4",Matches!$J$2:$J$201,0))="",INDEX(Matches!$H$2:$H$201,MATCH($A5&"-4",Matches!$J$2:$J$201,0))=""),"",IF(AND($C5<>"",INDEX(Matches!$F$2:$F$201,MATCH($A5&"-4",Matches!$J$2:$J$201,0))<>"",$C5>=INDEX(Matches!$F$2:$F$201,MATCH($A5&"-4",Matches!$J$2:$J$201,0))),"",IF(AND(J5=INDEX(Matches!$G$2:$G$201,MATCH($A5&"-4",Matches!$J$2:$J$201,0)),K5=INDEX(Matches!$H$2:$H$201,MATCH($A5&"-4",Matches!$J$2:$J$201,0))),5,IF(SIGN(J5-K5)<>SIGN(INDEX(Matches!$G$2:$G$201,MATCH($A5&"-4",Matches!$J$2:$J$201,0))-INDEX(Matches!$H$2:$H$201,MATCH($A5&"-4",Matches!$J$2:$J$201,0))),0,IF(J5-K5=INDEX(Matches!$G$2:$G$201,MATCH($A5&"-4",Matches!$J$2:$J$201,0))-INDEX(Matches!$H$2:$H$201,MATCH($A5&"-4",Matches!$J$2:$J$201,0)),3,2))))),"")) | AB5: =IF(OR($B5="",L5="",M5=""),"",IFERROR(IF(OR(INDEX(Matches!$I$2:$I$201,MATCH($A5&"-5",Matches!$J$2:$J$201,0))="Void",INDEX(Matches!$G$2:$G$201,MATCH($A5&"-5",Matches!$J$2:$J$201,0))="",INDEX(Matches!$H$2:$H$201,MATCH($A5&"-5",Matches!$J$2:$J$201,0))=""),"",IF(AND($C5<>"",INDEX(Matches!$F$2:$F$201,MATCH($A5&"-5",Matches!$J$2:$J$201,0))<>"",$C5>=INDEX(Matches!$F$2:$F$201,MATCH($A5&"-5",Matches!$J$2:$J$201,0))),"",IF(AND(L5=INDEX(Matches!$G$2:$G$201,MATCH($A5&"-5",Matches!$J$2:$J$201,0)),M5=INDEX(Matches!$H$2:$H$201,MATCH($A5&"-5",Matches!$J$2:$J$201,0))),5,IF(SIGN(L5-M5)<>SIGN(INDEX(Matches!$G$2:$G$201,MATCH($A5&"-5",Matches!$J$2:$J$201,0))-INDEX(Matches!$H$2:$H$201,MATCH($A5&"-5",Matches!$J$2:$J$201,0))),0,IF(L5-M5=INDEX(Matches!$G$2:$G$201,MATCH($A5&"-5",Matches!$J$2:$J$201,0))-INDEX(Matches!$H$2:$H$201,MATCH($A5&"-5",Matches!$J$2:$J$201,0)),3,2))))),"")) | AC5: =IF(OR($B5="",N5="",O5=""),"",IFERROR(IF(OR(INDEX(Matches!$I$2:$I$201,MATCH($A5&"-6",Matches!$J$2:$J$201,0))="Void",INDEX(Matches!$G$2:$G$201,MATCH($A5&"-6",Matches!$J$2:$J$201,0))="",INDEX(Matches!$H$2:$H$201,MATCH($A5&"-6",Matches!$J$2:$J$201,0))=""),"",IF(AND($C5<>"",INDEX(Matches!$F$2:$F$201,MATCH($A5&"-6",Matches!$J$2:$J$201,0))<>"",$C5>=INDEX(Matches!$F$2:$F$201,MATCH($A5&"-6",Matches!$J$2:$J$201,0))),"",IF(AND(N5=INDEX(Matches!$G$2:$G$201,MATCH($A5&"-6",Matches!$J$2:$J$201,0)),O5=INDEX(Matches!$H$2:$H$201,MATCH($A5&"-6",Matches!$J$2:$J$201,0))),5,IF(SIGN(N5-O5)<>SIGN(INDEX(Matches!$G$2:$G$201,MATCH($A5&"-6",Matches!$J$2:$J$201,0))-INDEX(Matches!$H$2:$H$201,MATCH($A5&"-6",Matches!$J$2:$J$201,0))),0,IF(N5-O5=INDEX(Matches!$G$2:$G$201,MATCH($A5&"-6",Matches!$J$2:$J$201,0))-INDEX(Matches!$H$2:$H$201,MATCH($A5&"-6",Matches!$J$2:$J$201,0)),3,2))))),"")) | AD5: =IF(OR($B5="",P5="",Q5=""),"",IFERROR(IF(OR(INDEX(Matches!$I$2:$I$201,MATCH($A5&"-7",Matches!$J$2:$J$201,0))="Void",INDEX(Matches!$G$2:$G$201,MATCH($A5&"-7",Matches!$J$2:$J$201,0))="",INDEX(Matches!$H$2:$H$201,MATCH($A5&"-7",Matches!$J$2:$J$201,0))=""),"",IF(AND($C5<>"",INDEX(Matches!$F$2:$F$201,MATCH($A5&"-7",Matches!$J$2:$J$201,0))<>"",$C5>=INDEX(Matches!$F$2:$F$201,MATCH($A5&"-7",Matches!$J$2:$J$201,0))),"",IF(AND(P5=INDEX(Matches!$G$2:$G$201,MATCH($A5&"-7",Matches!$J$2:$J$201,0)),Q5=INDEX(Matches!$H$2:$H$201,MATCH($A5&"-7",Matches!$J$2:$J$201,0))),5,IF(SIGN(P5-Q5)<>SIGN(INDEX(Matches!$G$2:$G$201,MATCH($A5&"-7",Matches!$J$2:$J$201,0))-INDEX(Matches!$H$2:$H$201,MATCH($A5&"-7",Matches!$J$2:$J$201,0))),0,IF(P5-Q5=INDEX(Matches!$G$2:$G$201,MATCH($A5&"-7",Matches!$J$2:$J$201,0))-INDEX(Matches!$H$2:$H$201,MATCH($A5&"-7",Matches!$J$2:$J$201,0)),3,2))))),"")) | AE5: =IF(OR($B5="",R5="",S5=""),"",IFERROR(IF(OR(INDEX(Matches!$I$2:$I$201,MATCH($A5&"-8",Matches!$J$2:$J$201,0))="Void",INDEX(Matches!$G$2:$G$201,MATCH($A5&"-8",Matches!$J$2:$J$201,0))="",INDEX(Matches!$H$2:$H$201,MATCH($A5&"-8",Matches!$J$2:$J$201,0))=""),"",IF(AND($C5<>"",INDEX(Matches!$F$2:$F$201,MATCH($A5&"-8",Matches!$J$2:$J$201,0))<>"",$C5>=INDEX(Matches!$F$2:$F$201,MATCH($A5&"-8",Matches!$J$2:$J$201,0))),"",IF(AND(R5=INDEX(Matches!$G$2:$G$201,MATCH($A5&"-8",Matches!$J$2:$J$201,0)),S5=INDEX(Matches!$H$2:$H$201,MATCH($A5&"-8",Matches!$J$2:$J$201,0))),5,IF(SIGN(R5-S5)<>SIGN(INDEX(Matches!$G$2:$G$201,MATCH($A5&"-8",Matches!$J$2:$J$201,0))-INDEX(Matches!$H$2:$H$201,MATCH($A5&"-8",Matches!$J$2:$J$201,0))),0,IF(R5-S5=INDEX(Matches!$G$2:$G$201,MATCH($A5&"-8",Matches!$J$2:$J$201,0))-INDEX(Matches!$H$2:$H$201,MATCH($A5&"-8",Matches!$J$2:$J$201,0)),3,2))))),"")) | AF5: =IF(OR($B5="",T5="",U5=""),"",IFERROR(IF(OR(INDEX(Matches!$I$2:$I$201,MATCH($A5&"-9",Matches!$J$2:$J$201,0))="Void",INDEX(Matches!$G$2:$G$201,MATCH($A5&"-9",Matches!$J$2:$J$201,0))="",INDEX(Matches!$H$2:$H$201,MATCH($A5&"-9",Matches!$J$2:$J$201,0))=""),"",IF(AND($C5<>"",INDEX(Matches!$F$2:$F$201,MATCH($A5&"-9",Matches!$J$2:$J$201,0))<>"",$C5>=INDEX(Matches!$F$2:$F$201,MATCH($A5&"-9",Matches!$J$2:$J$201,0))),"",IF(AND(T5=INDEX(Matches!$G$2:$G$201,MATCH($A5&"-9",Matches!$J$2:$J$201,0)),U5=INDEX(Matches!$H$2:$H$201,MATCH($A5&"-9",Matches!$J$2:$J$201,0))),5,IF(SIGN(T5-U5)<>SIGN(INDEX(Matches!$G$2:$G$201,MATCH($A5&"-9",Matches!$J$2:$J$201,0))-INDEX(Matches!$H$2:$H$201,MATCH($A5&"-9",Matches!$J$2:$J$201,0))),0,IF(T5-U5=INDEX(Matches!$G$2:$G$201,MATCH($A5&"-9",Matches!$J$2:$J$201,0))-INDEX(Matches!$H$2:$H$201,MATCH($A5&"-9",Matches!$J$2:$J$201,0)),3,2))))),"")) | AG5: =IF(OR($B5="",V5="",W5=""),"",IFERROR(IF(OR(INDEX(Matches!$I$2:$I$201,MATCH($A5&"-10",Matches!$J$2:$J$201,0))="Void",INDEX(Matches!$G$2:$G$201,MATCH($A5&"-10",Matches!$J$2:$J$201,0))="",INDEX(Matches!$H$2:$H$201,MATCH($A5&"-10",Matches!$J$2:$J$201,0))=""),"",IF(AND($C5<>"",INDEX(Matches!$F$2:$F$201,MATCH($A5&"-10",Matches!$J$2:$J$201,0))<>"",$C5>=INDEX(Matches!$F$2:$F$201,MATCH($A5&"-10",Matches!$J$2:$J$201,0))),"",IF(AND(V5=INDEX(Matches!$G$2:$G$201,MATCH($A5&"-10",Matches!$J$2:$J$201,0)),W5=INDEX(Matches!$H$2:$H$201,MATCH($A5&"-10",Matches!$J$2:$J$201,0))),5,IF(SIGN(V5-W5)<>SIGN(INDEX(Matches!$G$2:$G$201,MATCH($A5&"-10",Matches!$J$2:$J$201,0))-INDEX(Matches!$H$2:$H$201,MATCH($A5&"-10",Matches!$J$2:$J$201,0))),0,IF(V5-W5=INDEX(Matches!$G$2:$G$201,MATCH($A5&"-10",Matches!$J$2:$J$201,0))-INDEX(Matches!$H$2:$H$201,MATCH($A5&"-10",Matches!$J$2:$J$201,0)),3,2))))),"")) | AH5: =IF($B5="","",SUM(X5:AG5)) | AI5: =IF($B5="","",COUNTIF(X5:AG5,5)) | AJ5: =IF($B5="","",COUNTIF(X5:AG5,">=2")) | AK5: =IF($B5="","",COUNT(X5:AG5))
X6: =IF(OR($B6="",D6="",E6=""),"",IFERROR(IF(OR(INDEX(Matches!$I$2:$I$201,MATCH($A6&"-1",Matches!$J$2:$J$201,0))="Void",INDEX(Matches!$G$2:$G$201,MATCH($A6&"-1",Matches!$J$2:$J$201,0))="",INDEX(Matches!$H$2:$H$201,MATCH($A6&"-1",Matches!$J$2:$J$201,0))=""),"",IF(AND($C6<>"",INDEX(Matches!$F$2:$F$201,MATCH($A6&"-1",Matches!$J$2:$J$201,0))<>"",$C6>=INDEX(Matches!$F$2:$F$201,MATCH($A6&"-1",Matches!$J$2:$J$201,0))),"",IF(AND(D6=INDEX(Matches!$G$2:$G$201,MATCH($A6&"-1",Matches!$J$2:$J$201,0)),E6=INDEX(Matches!$H$2:$H$201,MATCH($A6&"-1",Matches!$J$2:$J$201,0))),5,IF(SIGN(D6-E6)<>SIGN(INDEX(Matches!$G$2:$G$201,MATCH($A6&"-1",Matches!$J$2:$J$201,0))-INDEX(Matches!$H$2:$H$201,MATCH($A6&"-1",Matches!$J$2:$J$201,0))),0,IF(D6-E6=INDEX(Matches!$G$2:$G$201,MATCH($A6&"-1",Matches!$J$2:$J$201,0))-INDEX(Matches!$H$2:$H$201,MATCH($A6&"-1",Matches!$J$2:$J$201,0)),3,2))))),"")) | Y6: =IF(OR($B6="",F6="",G6=""),"",IFERROR(IF(OR(INDEX(Matches!$I$2:$I$201,MATCH($A6&"-2",Matches!$J$2:$J$201,0))="Void",INDEX(Matches!$G$2:$G$201,MATCH($A6&"-2",Matches!$J$2:$J$201,0))="",INDEX(Matches!$H$2:$H$201,MATCH($A6&"-2",Matches!$J$2:$J$201,0))=""),"",IF(AND($C6<>"",INDEX(Matches!$F$2:$F$201,MATCH($A6&"-2",Matches!$J$2:$J$201,0))<>"",$C6>=INDEX(Matches!$F$2:$F$201,MATCH($A6&"-2",Matches!$J$2:$J$201,0))),"",IF(AND(F6=INDEX(Matches!$G$2:$G$201,MATCH($A6&"-2",Matches!$J$2:$J$201,0)),G6=INDEX(Matches!$H$2:$H$201,MATCH($A6&"-2",Matches!$J$2:$J$201,0))),5,IF(SIGN(F6-G6)<>SIGN(INDEX(Matches!$G$2:$G$201,MATCH($A6&"-2",Matches!$J$2:$J$201,0))-INDEX(Matches!$H$2:$H$201,MATCH($A6&"-2",Matches!$J$2:$J$201,0))),0,IF(F6-G6=INDEX(Matches!$G$2:$G$201,MATCH($A6&"-2",Matches!$J$2:$J$201,0))-INDEX(Matches!$H$2:$H$201,MATCH($A6&"-2",Matches!$J$2:$J$201,0)),3,2))))),"")) | Z6: =IF(OR($B6="",H6="",I6=""),"",IFERROR(IF(OR(INDEX(Matches!$I$2:$I$201,MATCH($A6&"-3",Matches!$J$2:$J$201,0))="Void",INDEX(Matches!$G$2:$G$201,MATCH($A6&"-3",Matches!$J$2:$J$201,0))="",INDEX(Matches!$H$2:$H$201,MATCH($A6&"-3",Matches!$J$2:$J$201,0))=""),"",IF(AND($C6<>"",INDEX(Matches!$F$2:$F$201,MATCH($A6&"-3",Matches!$J$2:$J$201,0))<>"",$C6>=INDEX(Matches!$F$2:$F$201,MATCH($A6&"-3",Matches!$J$2:$J$201,0))),"",IF(AND(H6=INDEX(Matches!$G$2:$G$201,MATCH($A6&"-3",Matches!$J$2:$J$201,0)),I6=INDEX(Matches!$H$2:$H$201,MATCH($A6&"-3",Matches!$J$2:$J$201,0))),5,IF(SIGN(H6-I6)<>SIGN(INDEX(Matches!$G$2:$G$201,MATCH($A6&"-3",Matches!$J$2:$J$201,0))-INDEX(Matches!$H$2:$H$201,MATCH($A6&"-3",Matches!$J$2:$J$201,0))),0,IF(H6-I6=INDEX(Matches!$G$2:$G$201,MATCH($A6&"-3",Matches!$J$2:$J$201,0))-INDEX(Matches!$H$2:$H$201,MATCH($A6&"-3",Matches!$J$2:$J$201,0)),3,2))))),"")) | AA6: =IF(OR($B6="",J6="",K6=""),"",IFERROR(IF(OR(INDEX(Matches!$I$2:$I$201,MATCH($A6&"-4",Matches!$J$2:$J$201,0))="Void",INDEX(Matches!$G$2:$G$201,MATCH($A6&"-4",Matches!$J$2:$J$201,0))="",INDEX(Matches!$H$2:$H$201,MATCH($A6&"-4",Matches!$J$2:$J$201,0))=""),"",IF(AND($C6<>"",INDEX(Matches!$F$2:$F$201,MATCH($A6&"-4",Matches!$J$2:$J$201,0))<>"",$C6>=INDEX(Matches!$F$2:$F$201,MATCH($A6&"-4",Matches!$J$2:$J$201,0))),"",IF(AND(J6=INDEX(Matches!$G$2:$G$201,MATCH($A6&"-4",Matches!$J$2:$J$201,0)),K6=INDEX(Matches!$H$2:$H$201,MATCH($A6&"-4",Matches!$J$2:$J$201,0))),5,IF(SIGN(J6-K6)<>SIGN(INDEX(Matches!$G$2:$G$201,MATCH($A6&"-4",Matches!$J$2:$J$201,0))-INDEX(Matches!$H$2:$H$201,MATCH($A6&"-4",Matches!$J$2:$J$201,0))),0,IF(J6-K6=INDEX(Matches!$G$2:$G$201,MATCH($A6&"-4",Matches!$J$2:$J$201,0))-INDEX(Matches!$H$2:$H$201,MATCH($A6&"-4",Matches!$J$2:$J$201,0)),3,2))))),"")) | AB6: =IF(OR($B6="",L6="",M6=""),"",IFERROR(IF(OR(INDEX(Matches!$I$2:$I$201,MATCH($A6&"-5",Matches!$J$2:$J$201,0))="Void",INDEX(Matches!$G$2:$G$201,MATCH($A6&"-5",Matches!$J$2:$J$201,0))="",INDEX(Matches!$H$2:$H$201,MATCH($A6&"-5",Matches!$J$2:$J$201,0))=""),"",IF(AND($C6<>"",INDEX(Matches!$F$2:$F$201,MATCH($A6&"-5",Matches!$J$2:$J$201,0))<>"",$C6>=INDEX(Matches!$F$2:$F$201,MATCH($A6&"-5",Matches!$J$2:$J$201,0))),"",IF(AND(L6=INDEX(Matches!$G$2:$G$201,MATCH($A6&"-5",Matches!$J$2:$J$201,0)),M6=INDEX(Matches!$H$2:$H$201,MATCH($A6&"-5",Matches!$J$2:$J$201,0))),5,IF(SIGN(L6-M6)<>SIGN(INDEX(Matches!$G$2:$G$201,MATCH($A6&"-5",Matches!$J$2:$J$201,0))-INDEX(Matches!$H$2:$H$201,MATCH($A6&"-5",Matches!$J$2:$J$201,0))),0,IF(L6-M6=INDEX(Matches!$G$2:$G$201,MATCH($A6&"-5",Matches!$J$2:$J$201,0))-INDEX(Matches!$H$2:$H$201,MATCH($A6&"-5",Matches!$J$2:$J$201,0)),3,2))))),"")) | AC6: =IF(OR($B6="",N6="",O6=""),"",IFERROR(IF(OR(INDEX(Matches!$I$2:$I$201,MATCH($A6&"-6",Matches!$J$2:$J$201,0))="Void",INDEX(Matches!$G$2:$G$201,MATCH($A6&"-6",Matches!$J$2:$J$201,0))="",INDEX(Matches!$H$2:$H$201,MATCH($A6&"-6",Matches!$J$2:$J$201,0))=""),"",IF(AND($C6<>"",INDEX(Matches!$F$2:$F$201,MATCH($A6&"-6",Matches!$J$2:$J$201,0))<>"",$C6>=INDEX(Matches!$F$2:$F$201,MATCH($A6&"-6",Matches!$J$2:$J$201,0))),"",IF(AND(N6=INDEX(Matches!$G$2:$G$201,MATCH($A6&"-6",Matches!$J$2:$J$201,0)),O6=INDEX(Matches!$H$2:$H$201,MATCH($A6&"-6",Matches!$J$2:$J$201,0))),5,IF(SIGN(N6-O6)<>SIGN(INDEX(Matches!$G$2:$G$201,MATCH($A6&"-6",Matches!$J$2:$J$201,0))-INDEX(Matches!$H$2:$H$201,MATCH($A6&"-6",Matches!$J$2:$J$201,0))),0,IF(N6-O6=INDEX(Matches!$G$2:$G$201,MATCH($A6&"-6",Matches!$J$2:$J$201,0))-INDEX(Matches!$H$2:$H$201,MATCH($A6&"-6",Matches!$J$2:$J$201,0)),3,2))))),"")) | AD6: =IF(OR($B6="",P6="",Q6=""),"",IFERROR(IF(OR(INDEX(Matches!$I$2:$I$201,MATCH($A6&"-7",Matches!$J$2:$J$201,0))="Void",INDEX(Matches!$G$2:$G$201,MATCH($A6&"-7",Matches!$J$2:$J$201,0))="",INDEX(Matches!$H$2:$H$201,MATCH($A6&"-7",Matches!$J$2:$J$201,0))=""),"",IF(AND($C6<>"",INDEX(Matches!$F$2:$F$201,MATCH($A6&"-7",Matches!$J$2:$J$201,0))<>"",$C6>=INDEX(Matches!$F$2:$F$201,MATCH($A6&"-7",Matches!$J$2:$J$201,0))),"",IF(AND(P6=INDEX(Matches!$G$2:$G$201,MATCH($A6&"-7",Matches!$J$2:$J$201,0)),Q6=INDEX(Matches!$H$2:$H$201,MATCH($A6&"-7",Matches!$J$2:$J$201,0))),5,IF(SIGN(P6-Q6)<>SIGN(INDEX(Matches!$G$2:$G$201,MATCH($A6&"-7",Matches!$J$2:$J$201,0))-INDEX(Matches!$H$2:$H$201,MATCH($A6&"-7",Matches!$J$2:$J$201,0))),0,IF(P6-Q6=INDEX(Matches!$G$2:$G$201,MATCH($A6&"-7",Matches!$J$2:$J$201,0))-INDEX(Matches!$H$2:$H$201,MATCH($A6&"-7",Matches!$J$2:$J$201,0)),3,2))))),"")) | AE6: =IF(OR($B6="",R6="",S6=""),"",IFERROR(IF(OR(INDEX(Matches!$I$2:$I$201,MATCH($A6&"-8",Matches!$J$2:$J$201,0))="Void",INDEX(Matches!$G$2:$G$201,MATCH($A6&"-8",Matches!$J$2:$J$201,0))="",INDEX(Matches!$H$2:$H$201,MATCH($A6&"-8",Matches!$J$2:$J$201,0))=""),"",IF(AND($C6<>"",INDEX(Matches!$F$2:$F$201,MATCH($A6&"-8",Matches!$J$2:$J$201,0))<>"",$C6>=INDEX(Matches!$F$2:$F$201,MATCH($A6&"-8",Matches!$J$2:$J$201,0))),"",IF(AND(R6=INDEX(Matches!$G$2:$G$201,MATCH($A6&"-8",Matches!$J$2:$J$201,0)),S6=INDEX(Matches!$H$2:$H$201,MATCH($A6&"-8",Matches!$J$2:$J$201,0))),5,IF(SIGN(R6-S6)<>SIGN(INDEX(Matches!$G$2:$G$201,MATCH($A6&"-8",Matches!$J$2:$J$201,0))-INDEX(Matches!$H$2:$H$201,MATCH($A6&"-8",Matches!$J$2:$J$201,0))),0,IF(R6-S6=INDEX(Matches!$G$2:$G$201,MATCH($A6&"-8",Matches!$J$2:$J$201,0))-INDEX(Matches!$H$2:$H$201,MATCH($A6&"-8",Matches!$J$2:$J$201,0)),3,2))))),"")) | AF6: =IF(OR($B6="",T6="",U6=""),"",IFERROR(IF(OR(INDEX(Matches!$I$2:$I$201,MATCH($A6&"-9",Matches!$J$2:$J$201,0))="Void",INDEX(Matches!$G$2:$G$201,MATCH($A6&"-9",Matches!$J$2:$J$201,0))="",INDEX(Matches!$H$2:$H$201,MATCH($A6&"-9",Matches!$J$2:$J$201,0))=""),"",IF(AND($C6<>"",INDEX(Matches!$F$2:$F$201,MATCH($A6&"-9",Matches!$J$2:$J$201,0))<>"",$C6>=INDEX(Matches!$F$2:$F$201,MATCH($A6&"-9",Matches!$J$2:$J$201,0))),"",IF(AND(T6=INDEX(Matches!$G$2:$G$201,MATCH($A6&"-9",Matches!$J$2:$J$201,0)),U6=INDEX(Matches!$H$2:$H$201,MATCH($A6&"-9",Matches!$J$2:$J$201,0))),5,IF(SIGN(T6-U6)<>SIGN(INDEX(Matches!$G$2:$G$201,MATCH($A6&"-9",Matches!$J$2:$J$201,0))-INDEX(Matches!$H$2:$H$201,MATCH($A6&"-9",Matches!$J$2:$J$201,0))),0,IF(T6-U6=INDEX(Matches!$G$2:$G$201,MATCH($A6&"-9",Matches!$J$2:$J$201,0))-INDEX(Matches!$H$2:$H$201,MATCH($A6&"-9",Matches!$J$2:$J$201,0)),3,2))))),"")) | AG6: =IF(OR($B6="",V6="",W6=""),"",IFERROR(IF(OR(INDEX(Matches!$I$2:$I$201,MATCH($A6&"-10",Matches!$J$2:$J$201,0))="Void",INDEX(Matches!$G$2:$G$201,MATCH($A6&"-10",Matches!$J$2:$J$201,0))="",INDEX(Matches!$H$2:$H$201,MATCH($A6&"-10",Matches!$J$2:$J$201,0))=""),"",IF(AND($C6<>"",INDEX(Matches!$F$2:$F$201,MATCH($A6&"-10",Matches!$J$2:$J$201,0))<>"",$C6>=INDEX(Matches!$F$2:$F$201,MATCH($A6&"-10",Matches!$J$2:$J$201,0))),"",IF(AND(V6=INDEX(Matches!$G$2:$G$201,MATCH($A6&"-10",Matches!$J$2:$J$201,0)),W6=INDEX(Matches!$H$2:$H$201,MATCH($A6&"-10",Matches!$J$2:$J$201,0))),5,IF(SIGN(V6-W6)<>SIGN(INDEX(Matches!$G$2:$G$201,MATCH($A6&"-10",Matches!$J$2:$J$201,0))-INDEX(Matches!$H$2:$H$201,MATCH($A6&"-10",Matches!$J$2:$J$201,0))),0,IF(V6-W6=INDEX(Matches!$G$2:$G$201,MATCH($A6&"-10",Matches!$J$2:$J$201,0))-INDEX(Matches!$H$2:$H$201,MATCH($A6&"-10",Matches!$J$2:$J$201,0)),3,2))))),"")) | AH6: =IF($B6="","",SUM(X6:AG6)) | AI6: =IF($B6="","",COUNTIF(X6:AG6,5)) | AJ6: =IF($B6="","",COUNTIF(X6:AG6,">=2")) | AK6: =IF($B6="","",COUNT(X6:AG6))
X7: =IF(OR($B7="",D7="",E7=""),"",IFERROR(IF(OR(INDEX(Matches!$I$2:$I$201,MATCH($A7&"-1",Matches!$J$2:$J$201,0))="Void",INDEX(Matches!$G$2:$G$201,MATCH($A7&"-1",Matches!$J$2:$J$201,0))="",INDEX(Matches!$H$2:$H$201,MATCH($A7&"-1",Matches!$J$2:$J$201,0))=""),"",IF(AND($C7<>"",INDEX(Matches!$F$2:$F$201,MATCH($A7&"-1",Matches!$J$2:$J$201,0))<>"",$C7>=INDEX(Matches!$F$2:$F$201,MATCH($A7&"-1",Matches!$J$2:$J$201,0))),"",IF(AND(D7=INDEX(Matches!$G$2:$G$201,MATCH($A7&"-1",Matches!$J$2:$J$201,0)),E7=INDEX(Matches!$H$2:$H$201,MATCH($A7&"-1",Matches!$J$2:$J$201,0))),5,IF(SIGN(D7-E7)<>SIGN(INDEX(Matches!$G$2:$G$201,MATCH($A7&"-1",Matches!$J$2:$J$201,0))-INDEX(Matches!$H$2:$H$201,MATCH($A7&"-1",Matches!$J$2:$J$201,0))),0,IF(D7-E7=INDEX(Matches!$G$2:$G$201,MATCH($A7&"-1",Matches!$J$2:$J$201,0))-INDEX(Matches!$H$2:$H$201,MATCH($A7&"-1",Matches!$J$2:$J$201,0)),3,2))))),"")) | Y7: =IF(OR($B7="",F7="",G7=""),"",IFERROR(IF(OR(INDEX(Matches!$I$2:$I$201,MATCH($A7&"-2",Matches!$J$2:$J$201,0))="Void",INDEX(Matches!$G$2:$G$201,MATCH($A7&"-2",Matches!$J$2:$J$201,0))="",INDEX(Matches!$H$2:$H$201,MATCH($A7&"-2",Matches!$J$2:$J$201,0))=""),"",IF(AND($C7<>"",INDEX(Matches!$F$2:$F$201,MATCH($A7&"-2",Matches!$J$2:$J$201,0))<>"",$C7>=INDEX(Matches!$F$2:$F$201,MATCH($A7&"-2",Matches!$J$2:$J$201,0))),"",IF(AND(F7=INDEX(Matches!$G$2:$G$201,MATCH($A7&"-2",Matches!$J$2:$J$201,0)),G7=INDEX(Matches!$H$2:$H$201,MATCH($A7&"-2",Matches!$J$2:$J$201,0))),5,IF(SIGN(F7-G7)<>SIGN(INDEX(Matches!$G$2:$G$201,MATCH($A7&"-2",Matches!$J$2:$J$201,0))-INDEX(Matches!$H$2:$H$201,MATCH($A7&"-2",Matches!$J$2:$J$201,0))),0,IF(F7-G7=INDEX(Matches!$G$2:$G$201,MATCH($A7&"-2",Matches!$J$2:$J$201,0))-INDEX(Matches!$H$2:$H$201,MATCH($A7&"-2",Matches!$J$2:$J$201,0)),3,2))))),"")) | Z7: =IF(OR($B7="",H7="",I7=""),"",IFERROR(IF(OR(INDEX(Matches!$I$2:$I$201,MATCH($A7&"-3",Matches!$J$2:$J$201,0))="Void",INDEX(Matches!$G$2:$G$201,MATCH($A7&"-3",Matches!$J$2:$J$201,0))="",INDEX(Matches!$H$2:$H$201,MATCH($A7&"-3",Matches!$J$2:$J$201,0))=""),"",IF(AND($C7<>"",INDEX(Matches!$F$2:$F$201,MATCH($A7&"-3",Matches!$J$2:$J$201,0))<>"",$C7>=INDEX(Matches!$F$2:$F$201,MATCH($A7&"-3",Matches!$J$2:$J$201,0))),"",IF(AND(H7=INDEX(Matches!$G$2:$G$201,MATCH($A7&"-3",Matches!$J$2:$J$201,0)),I7=INDEX(Matches!$H$2:$H$201,MATCH($A7&"-3",Matches!$J$2:$J$201,0))),5,IF(SIGN(H7-I7)<>SIGN(INDEX(Matches!$G$2:$G$201,MATCH($A7&"-3",Matches!$J$2:$J$201,0))-INDEX(Matches!$H$2:$H$201,MATCH($A7&"-3",Matches!$J$2:$J$201,0))),0,IF(H7-I7=INDEX(Matches!$G$2:$G$201,MATCH($A7&"-3",Matches!$J$2:$J$201,0))-INDEX(Matches!$H$2:$H$201,MATCH($A7&"-3",Matches!$J$2:$J$201,0)),3,2))))),"")) | AA7: =IF(OR($B7="",J7="",K7=""),"",IFERROR(IF(OR(INDEX(Matches!$I$2:$I$201,MATCH($A7&"-4",Matches!$J$2:$J$201,0))="Void",INDEX(Matches!$G$2:$G$201,MATCH($A7&"-4",Matches!$J$2:$J$201,0))="",INDEX(Matches!$H$2:$H$201,MATCH($A7&"-4",Matches!$J$2:$J$201,0))=""),"",IF(AND($C7<>"",INDEX(Matches!$F$2:$F$201,MATCH($A7&"-4",Matches!$J$2:$J$201,0))<>"",$C7>=INDEX(Matches!$F$2:$F$201,MATCH($A7&"-4",Matches!$J$2:$J$201,0))),"",IF(AND(J7=INDEX(Matches!$G$2:$G$201,MATCH($A7&"-4",Matches!$J$2:$J$201,0)),K7=INDEX(Matches!$H$2:$H$201,MATCH($A7&"-4",Matches!$J$2:$J$201,0))),5,IF(SIGN(J7-K7)<>SIGN(INDEX(Matches!$G$2:$G$201,MATCH($A7&"-4",Matches!$J$2:$J$201,0))-INDEX(Matches!$H$2:$H$201,MATCH($A7&"-4",Matches!$J$2:$J$201,0))),0,IF(J7-K7=INDEX(Matches!$G$2:$G$201,MATCH($A7&"-4",Matches!$J$2:$J$201,0))-INDEX(Matches!$H$2:$H$201,MATCH($A7&"-4",Matches!$J$2:$J$201,0)),3,2))))),"")) | AB7: =IF(OR($B7="",L7="",M7=""),"",IFERROR(IF(OR(INDEX(Matches!$I$2:$I$201,MATCH($A7&"-5",Matches!$J$2:$J$201,0))="Void",INDEX(Matches!$G$2:$G$201,MATCH($A7&"-5",Matches!$J$2:$J$201,0))="",INDEX(Matches!$H$2:$H$201,MATCH($A7&"-5",Matches!$J$2:$J$201,0))=""),"",IF(AND($C7<>"",INDEX(Matches!$F$2:$F$201,MATCH($A7&"-5",Matches!$J$2:$J$201,0))<>"",$C7>=INDEX(Matches!$F$2:$F$201,MATCH($A7&"-5",Matches!$J$2:$J$201,0))),"",IF(AND(L7=INDEX(Matches!$G$2:$G$201,MATCH($A7&"-5",Matches!$J$2:$J$201,0)),M7=INDEX(Matches!$H$2:$H$201,MATCH($A7&"-5",Matches!$J$2:$J$201,0))),5,IF(SIGN(L7-M7)<>SIGN(INDEX(Matches!$G$2:$G$201,MATCH($A7&"-5",Matches!$J$2:$J$201,0))-INDEX(Matches!$H$2:$H$201,MATCH($A7&"-5",Matches!$J$2:$J$201,0))),0,IF(L7-M7=INDEX(Matches!$G$2:$G$201,MATCH($A7&"-5",Matches!$J$2:$J$201,0))-INDEX(Matches!$H$2:$H$201,MATCH($A7&"-5",Matches!$J$2:$J$201,0)),3,2))))),"")) | AC7: =IF(OR($B7="",N7="",O7=""),"",IFERROR(IF(OR(INDEX(Matches!$I$2:$I$201,MATCH($A7&"-6",Matches!$J$2:$J$201,0))="Void",INDEX(Matches!$G$2:$G$201,MATCH($A7&"-6",Matches!$J$2:$J$201,0))="",INDEX(Matches!$H$2:$H$201,MATCH($A7&"-6",Matches!$J$2:$J$201,0))=""),"",IF(AND($C7<>"",INDEX(Matches!$F$2:$F$201,MATCH($A7&"-6",Matches!$J$2:$J$201,0))<>"",$C7>=INDEX(Matches!$F$2:$F$201,MATCH($A7&"-6",Matches!$J$2:$J$201,0))),"",IF(AND(N7=INDEX(Matches!$G$2:$G$201,MATCH($A7&"-6",Matches!$J$2:$J$201,0)),O7=INDEX(Matches!$H$2:$H$201,MATCH($A7&"-6",Matches!$J$2:$J$201,0))),5,IF(SIGN(N7-O7)<>SIGN(INDEX(Matches!$G$2:$G$201,MATCH($A7&"-6",Matches!$J$2:$J$201,0))-INDEX(Matches!$H$2:$H$201,MATCH($A7&"-6",Matches!$J$2:$J$201,0))),0,IF(N7-O7=INDEX(Matches!$G$2:$G$201,MATCH($A7&"-6",Matches!$J$2:$J$201,0))-INDEX(Matches!$H$2:$H$201,MATCH($A7&"-6",Matches!$J$2:$J$201,0)),3,2))))),"")) | AD7: =IF(OR($B7="",P7="",Q7=""),"",IFERROR(IF(OR(INDEX(Matches!$I$2:$I$201,MATCH($A7&"-7",Matches!$J$2:$J$201,0))="Void",INDEX(Matches!$G$2:$G$201,MATCH($A7&"-7",Matches!$J$2:$J$201,0))="",INDEX(Matches!$H$2:$H$201,MATCH($A7&"-7",Matches!$J$2:$J$201,0))=""),"",IF(AND($C7<>"",INDEX(Matches!$F$2:$F$201,MATCH($A7&"-7",Matches!$J$2:$J$201,0))<>"",$C7>=INDEX(Matches!$F$2:$F$201,MATCH($A7&"-7",Matches!$J$2:$J$201,0))),"",IF(AND(P7=INDEX(Matches!$G$2:$G$201,MATCH($A7&"-7",Matches!$J$2:$J$201,0)),Q7=INDEX(Matches!$H$2:$H$201,MATCH($A7&"-7",Matches!$J$2:$J$201,0))),5,IF(SIGN(P7-Q7)<>SIGN(INDEX(Matches!$G$2:$G$201,MATCH($A7&"-7",Matches!$J$2:$J$201,0))-INDEX(Matches!$H$2:$H$201,MATCH($A7&"-7",Matches!$J$2:$J$201,0))),0,IF(P7-Q7=INDEX(Matches!$G$2:$G$201,MATCH($A7&"-7",Matches!$J$2:$J$201,0))-INDEX(Matches!$H$2:$H$201,MATCH($A7&"-7",Matches!$J$2:$J$201,0)),3,2))))),"")) | AE7: =IF(OR($B7="",R7="",S7=""),"",IFERROR(IF(OR(INDEX(Matches!$I$2:$I$201,MATCH($A7&"-8",Matches!$J$2:$J$201,0))="Void",INDEX(Matches!$G$2:$G$201,MATCH($A7&"-8",Matches!$J$2:$J$201,0))="",INDEX(Matches!$H$2:$H$201,MATCH($A7&"-8",Matches!$J$2:$J$201,0))=""),"",IF(AND($C7<>"",INDEX(Matches!$F$2:$F$201,MATCH($A7&"-8",Matches!$J$2:$J$201,0))<>"",$C7>=INDEX(Matches!$F$2:$F$201,MATCH($A7&"-8",Matches!$J$2:$J$201,0))),"",IF(AND(R7=INDEX(Matches!$G$2:$G$201,MATCH($A7&"-8",Matches!$J$2:$J$201,0)),S7=INDEX(Matches!$H$2:$H$201,MATCH($A7&"-8",Matches!$J$2:$J$201,0))),5,IF(SIGN(R7-S7)<>SIGN(INDEX(Matches!$G$2:$G$201,MATCH($A7&"-8",Matches!$J$2:$J$201,0))-INDEX(Matches!$H$2:$H$201,MATCH($A7&"-8",Matches!$J$2:$J$201,0))),0,IF(R7-S7=INDEX(Matches!$G$2:$G$201,MATCH($A7&"-8",Matches!$J$2:$J$201,0))-INDEX(Matches!$H$2:$H$201,MATCH($A7&"-8",Matches!$J$2:$J$201,0)),3,2))))),"")) | AF7: =IF(OR($B7="",T7="",U7=""),"",IFERROR(IF(OR(INDEX(Matches!$I$2:$I$201,MATCH($A7&"-9",Matches!$J$2:$J$201,0))="Void",INDEX(Matches!$G$2:$G$201,MATCH($A7&"-9",Matches!$J$2:$J$201,0))="",INDEX(Matches!$H$2:$H$201,MATCH($A7&"-9",Matches!$J$2:$J$201,0))=""),"",IF(AND($C7<>"",INDEX(Matches!$F$2:$F$201,MATCH($A7&"-9",Matches!$J$2:$J$201,0))<>"",$C7>=INDEX(Matches!$F$2:$F$201,MATCH($A7&"-9",Matches!$J$2:$J$201,0))),"",IF(AND(T7=INDEX(Matches!$G$2:$G$201,MATCH($A7&"-9",Matches!$J$2:$J$201,0)),U7=INDEX(Matches!$H$2:$H$201,MATCH($A7&"-9",Matches!$J$2:$J$201,0))),5,IF(SIGN(T7-U7)<>SIGN(INDEX(Matches!$G$2:$G$201,MATCH($A7&"-9",Matches!$J$2:$J$201,0))-INDEX(Matches!$H$2:$H$201,MATCH($A7&"-9",Matches!$J$2:$J$201,0))),0,IF(T7-U7=INDEX(Matches!$G$2:$G$201,MATCH($A7&"-9",Matches!$J$2:$J$201,0))-INDEX(Matches!$H$2:$H$201,MATCH($A7&"-9",Matches!$J$2:$J$201,0)),3,2))))),"")) | AG7: =IF(OR($B7="",V7="",W7=""),"",IFERROR(IF(OR(INDEX(Matches!$I$2:$I$201,MATCH($A7&"-10",Matches!$J$2:$J$201,0))="Void",INDEX(Matches!$G$2:$G$201,MATCH($A7&"-10",Matches!$J$2:$J$201,0))="",INDEX(Matches!$H$2:$H$201,MATCH($A7&"-10",Matches!$J$2:$J$201,0))=""),"",IF(AND($C7<>"",INDEX(Matches!$F$2:$F$201,MATCH($A7&"-10",Matches!$J$2:$J$201,0))<>"",$C7>=INDEX(Matches!$F$2:$F$201,MATCH($A7&"-10",Matches!$J$2:$J$201,0))),"",IF(AND(V7=INDEX(Matches!$G$2:$G$201,MATCH($A7&"-10",Matches!$J$2:$J$201,0)),W7=INDEX(Matches!$H$2:$H$201,MATCH($A7&"-10",Matches!$J$2:$J$201,0))),5,IF(SIGN(V7-W7)<>SIGN(INDEX(Matches!$G$2:$G$201,MATCH($A7&"-10",Matches!$J$2:$J$201,0))-INDEX(Matches!$H$2:$H$201,MATCH($A7&"-10",Matches!$J$2:$J$201,0))),0,IF(V7-W7=INDEX(Matches!$G$2:$G$201,MATCH($A7&"-10",Matches!$J$2:$J$201,0))-INDEX(Matches!$H$2:$H$201,MATCH($A7&"-10",Matches!$J$2:$J$201,0)),3,2))))),"")) | AH7: =IF($B7="","",SUM(X7:AG7)) | AI7: =IF($B7="","",COUNTIF(X7:AG7,5)) | AJ7: =IF($B7="","",COUNTIF(X7:AG7,">=2")) | AK7: =IF($B7="","",COUNT(X7:AG7))
